Workbook
Name Lookup_Sheets: 'Term staffing'!$AM$2:$AM$14
Name Lookup_Sheets: #REF!

Sheet Week 1
A1: Role (uploaded) | B1: Pager No (uploaded) | C1: Cost Centre (Not Used) | D1: Name (Not Used) | E1: Emp No | F1: Monday | G1: Tuesday | H1: Wednesday | I1: Thursday | J1: Friday | K1: Saturday | L1: Sunday | M1: ONCALL Workrule Code
A2: Date | F2: 46146 | G2: =F2+1 -> 46147 | H2: =G2+1 -> 46148 | I2: =H2+1 -> 46149 | J2: =I2+1 -> 46150 | K2: =J2+1 -> 46151 | L2: =K2+1 -> 46152
A3: Week | B3: 1
A4: PAY PERIOD WEEK | C4: 1 | D4: PAEDIATRIC EMERGENCY DEPARTMENT ROSTER - Term 2 2026
D6: AM SMS | F6: =COUNTIF(F$21:F$49,"0800-1???")-COUNTIFS(F$48,"0800-1???",$D$48,"Locum")-COUNTIFS(F$49,"0800-1???",$D$49,"Locum") -> 3 | G6: =COUNTIF(G$21:G$49,"0800-1???")-COUNTIFS(G$48,"0800-1???",$D$48,"Locum")-COUNTIFS(G$49,"0800-1???",$D$49,"Locum") -> 4 | H6: =COUNTIF(H$21:H$49,"0800-1???")-COUNTIFS(H$48,"0800-1???",$D$48,"Locum")-COUNTIFS(H$49,"0800-1???",$D$49,"Locum") -> 3 | I6: =COUNTIF(I$21:I$49,"0800-1???")-COUNTIFS(I$48,"0800-1???",$D$48,"Locum")-COUNTIFS(I$49,"0800-1???",$D$49,"Locum") -> 2 | J6: =COUNTIF(J$21:J$49,"0800-1???")-COUNTIFS(J$48,"0800-1???",$D$48,"Locum")-COUNTIFS(J$49,"0800-1???",$D$49,"Locum") -> 3 | K6: =COUNTIF(K$21:K$49,"0800-1???")-COUNTIFS(K$48,"0800-1???",$D$48,"Locum")-COUNTIFS(K$49,"0800-1???",$D$49,"Locum") -> 2 | L6: =COUNTIF(L$21:L$49,"0800-1???")-COUNTIFS(L$48,"0800-1???",$D$48,"Locum")-COUNTIFS(L$49,"0800-1???",$D$49,"Locum") -> 2
D7: AM JMS | F7: =COUNTIF(F$54:F$102,"0800-1???") -> 9 | G7: =COUNTIF(G$54:G$102,"0800-1???") -> 3 | H7: =COUNTIF(H$54:H$102,"0800-1???") -> 4 | I7: =COUNTIF(I$54:I$102,"0800-1???") -> 7 | J7: =COUNTIF(J$54:J$102,"0800-1???") -> 4 | K7: =COUNTIF(K$54:K$102,"0800-1???") -> 4 | L7: =COUNTIF(L$54:L$102,"0800-1???") -> 4
D8: AM Total | F8: =F6+F7 -> 12 | G8: =G6+G7 -> 7 | H8: =H6+H7 -> 7 | I8: =I6+I7 -> 9 | J8: =J6+J7 -> 7 | K8: =K6+K7 -> 6 | L8: =L6+L7 -> 6
D10: SMS Swing | F10: =COUNTIF(F$21:F$49,"1100-????")-COUNTIFS(F$48,"1100-????",$D$48,"Locum")-COUNTIFS(F$49,"1100-????",$D$49,"Locum") -> 0 | G10: =COUNTIF(G$21:G$49,"1100-????")-COUNTIFS(G$48,"1100-????",$D$48,"Locum")-COUNTIFS(G$49,"1100-????",$D$49,"Locum") -> 0 | H10: =COUNTIF(H$21:H$49,"1100-????")-COUNTIFS(H$48,"1100-????",$D$48,"Locum")-COUNTIFS(H$49,"1100-????",$D$49,"Locum") -> 0 | I10: =COUNTIF(I$21:I$49,"1100-????")-COUNTIFS(I$48,"1100-????",$D$48,"Locum")-COUNTIFS(I$49,"1100-????",$D$49,"Locum") -> 0 | J10: =COUNTIF(J$21:J$49,"1100-????")-COUNTIFS(J$48,"1100-????",$D$48,"Locum")-COUNTIFS(J$49,"1100-????",$D$49,"Locum") -> 0 | K10: =COUNTIF(K$21:K$49,"1100-????")-COUNTIFS(K$48,"1100-????",$D$48,"Locum")-COUNTIFS(K$49,"1100-????",$D$49,"Locum") -> 0 | L10: =COUNTIF(L$21:L$49,"1100-????")-COUNTIFS(L$48,"1100-????",$D$48,"Locum")-COUNTIFS(L$49,"1100-????",$D$49,"Locum") -> 0
D11: JMS Swing | F11: =COUNTIF(F$54:F$102,"1100-????") -> 0 | G11: =COUNTIF(G$54:G$102,"1100-????") -> 0 | H11: =COUNTIF(H$54:H$102,"1100-????") -> 0 | I11: =COUNTIF(I$54:I$102,"1100-????") -> 0 | J11: =COUNTIF(J$54:J$102,"1100-????") -> 0 | K11: =COUNTIF(K$54:K$102,"1100-????") -> 0 | L11: =COUNTIF(L$54:L$102,"1100-????") -> 0
D12: PM SMS | F12: =COUNTIF(F$21:F$49,"1???-00?0")-COUNTIFS(F$48,"1???-00?0",$D$48,"Locum")-COUNTIFS(F$49,"1???-00?0",$D$49,"Locum") -> 3 | G12: =COUNTIF(G$21:G$49,"1???-00?0")-COUNTIFS(G$48,"1???-00?0",$D$48,"Locum")-COUNTIFS(G$49,"1???-00?0",$D$49,"Locum") -> 3 | H12: =COUNTIF(H$21:H$49,"1???-00?0")-COUNTIFS(H$48,"1???-00?0",$D$48,"Locum")-COUNTIFS(H$49,"1???-00?0",$D$49,"Locum") -> 2 | I12: =COUNTIF(I$21:I$49,"1???-00?0")-COUNTIFS(I$48,"1???-00?0",$D$48,"Locum")-COUNTIFS(I$49,"1???-00?0",$D$49,"Locum") -> 3 | J12: =COUNTIF(J$21:J$49,"1???-00?0")-COUNTIFS(J$48,"1???-00?0",$D$48,"Locum")-COUNTIFS(J$49,"1???-00?0",$D$49,"Locum") -> 3 | K12: =COUNTIF(K$21:K$49,"1???-00?0")-COUNTIFS(K$48,"1???-00?0",$D$48,"Locum")-COUNTIFS(K$49,"1???-00?0",$D$49,"Locum") -> 2 | L12: =COUNTIF(L$21:L$49,"1???-00?0")-COUNTIFS(L$48,"1???-00?0",$D$48,"Locum")-COUNTIFS(L$49,"1???-00?0",$D$49,"Locum") -> 2
D13: PM JMS | F13: =COUNTIF(F$54:F$102,"1???-0000*") -> 9 | G13: =COUNTIF(G$54:G$102,"1???-0000*") -> 7 | H13: =COUNTIF(H$54:H$102,"1???-0000*") -> 5 | I13: =COUNTIF(I$54:I$102,"1???-0000*") -> 7 | J13: =COUNTIF(J$54:J$102,"1???-0000*") -> 7 | K13: =COUNTIF(K$54:K$102,"1???-0000*") -> 8 | L13: =COUNTIF(L$54:L$102,"1???-0000*") -> 8
D14: PM Total | F14: =F12+F13 -> 12 | G14: =G12+G13 -> 10 | H14: =H12+H13 -> 7 | I14: =I12+I13 -> 10 | J14: =J12+J13 -> 10 | K14: =K12+K13 -> 10 | L14: =L12+L13 -> 10
D16: Night | F16: =COUNTIF(F$54:F$99,"2300-0830") -> 4 | G16: =COUNTIF(G$54:G$99,"2300-0830") -> 4 | H16: =COUNTIF(H$54:H$99,"2300-0830") -> 4 | I16: =COUNTIF(I$54:I$99,"2300-0830") -> 4 | J16: =COUNTIF(J$54:J$99,"2300-0830") -> 5 | K16: =COUNTIF(K$54:K$99,"2300-0830") -> 5 | L16: =COUNTIF(L$54:L$99,"2300-0830") -> 5
D18: Name | E18: Emp No | F18: Monday | G18: Tuesday | H18: Wednesday | I18: Thursday | J18: Friday | K18: Saturday | L18: Sunday | N18: Weekly | O18: Leave | P18: Total | R18: PP | S18: PP Contracted
F19: =F2 -> 46146 | G19: =F19+1 -> 46147 | H19: =G19+1 -> 46148 | I19: =H19+1 -> 46149 | J19: =I19+1 -> 46150 | K19: =J19+1 -> 46151 | L19: =K19+1 -> 46152 | N19: (shifts) | O19: (shifts) | R19: (shifts) | S19: (shifts) | U19: AM | V19: PM | W19: CS | X19: Swing | Y19: Weekend
A20: Staff Specialist | D20: Staff Specialist
A21: Paediatric Emergency Consultant | D21: Dr Adam West | E21: =IFERROR(VLOOKUP(D21,'Employee Numbers'!$A$3:$B$84,2,FALSE),"NOT FOUND") -> 287628 | F21: 0800-1730 CS | G21: 0800-1730 CS | H21: 0800-1730 CS | J21: 1430-0000 | N21: {=((SUM(IFERROR((TEXT(IF(ISNUMBER(SEARCH("-", F21:L21)), MID(F21:L21, SEARCH("-", F21:L21) + 1, 4), ""), "00\:00") - TEXT(IF(ISNUMBER(SEARCH("-", F21:L21)), MID(F21:L21, SEARCH("-", F21:L21) - 4, 4), ""), "00\:00") + IF(TEXT(IF(ISNUMBER(SEARCH("-", F21:L21)), MID(F21:L21, SEARCH("-", F21:L21) + 1, 4), ""), "00\:00") < TEXT(IF(ISNUMBER(SEARCH("-", F21:L21)), MID(F21:L21, SEARCH("-", F21:L21) - 4, 4), ""), "00\:00"), 1, 0))*24,""))))/9.5} -> 4 | P21: =N21+O21 -> 4 | R21: =IF($C$4=1,SUM(P21+INDIRECT("'Week "&($B$3+1)&"'!P"&(ROW()))),IF($C$4=2,SUM(P21+INDIRECT("'Week "&($B$3-1)&"'!P"&(ROW()))))) -> 8 | S21: =(IFERROR(VLOOKUP(D21,'Employee Numbers'!$A$3:$C$84,3,FALSE),"NOT FOUND"))*8 -> 8 | U21: =COUNTIF(E21:K21,"0800-1730") -> 0 | V21: =COUNTIF(F21:L21,"1???-00?0") -> 1 | W21: =COUNTIF(F21:L21,"*0800-1730*CS*")+COUNTIF(F21:L21,"*0800-1730*DEMT*") -> 3 | Y21: =COUNTIF(K21:L21,"???0-*") -> 0
A22: Paediatric Emergency Consultant | D22: Dr Toby VanHest | E22: =IFERROR(VLOOKUP(D22,'Employee Numbers'!$A$3:$B$83,2,FALSE),"NOT FOUND") -> 609660 | F22: 0800-1730 CS | G22: 0800-1730 CS | K22: 0800-1730 | L22: 0800-1730 | N22: {=((SUM(IFERROR((TEXT(IF(ISNUMBER(SEARCH("-", F22:L22)), MID(F22:L22, SEARCH("-", F22:L22) + 1, 4), ""), "00\:00") - TEXT(IF(ISNUMBER(SEARCH("-", F22:L22)), MID(F22:L22, SEARCH("-", F22:L22) - 4, 4), ""), "00\:00") + IF(TEXT(IF(ISNUMBER(SEARCH("-", F22:L22)), MID(F22:L22, SEARCH("-", F22:L22) + 1, 4), ""), "00\:00") < TEXT(IF(ISNUMBER(SEARCH("-", F22:L22)), MID(F22:L22, SEARCH("-", F22:L22) - 4, 4), ""), "00\:00"), 1, 0))*24,""))))/9.5} -> 4 | P22: =N22+O22 -> 4 | R22: =IF($C$4=1,SUM(P22+INDIRECT("'Week "&($B$3+1)&"'!P"&(ROW()))),IF($C$4=2,SUM(P22+INDIRECT("'Week "&($B$3-1)&"'!P"&(ROW()))))) -> 8 | S22: =(IFERROR(VLOOKUP(D22,'Employee Numbers'!$A$3:$C$84,3,FALSE),"NOT FOUND"))*8 -> 8 | U22: =COUNTIF(E22:K22,"0800-1730") -> 1 | V22: =COUNTIF(F22:L22,"1???-00?0") -> 0 | W22: =COUNTIF(F22:L22,"*0800-1730*CS*")+COUNTIF(F22:L22,"*0800-1730*DEMT*") -> 2 | Y22: =COUNTIF(K22:L22,"???0-*") -> 2
A23: Paediatric Emergency Consultant | D23: Dr Bob Seith | E23: =IFERROR(VLOOKUP(D23,'Employee Numbers'!$A$3:$B$83,2,FALSE),"NOT FOUND") -> 610036 | F23: 0800-1730 DEMT | G23: 1430-0000 | H23: 1430-2300 | I23: 0800-1730CS | N23: {=((SUM(IFERROR((TEXT(IF(ISNUMBER(SEARCH("-", F23:L23)), MID(F23:L23, SEARCH("-", F23:L23) + 1, 4), ""), "00\:00") - TEXT(IF(ISNUMBER(SEARCH("-", F23:L23)), MID(F23:L23, SEARCH("-", F23:L23) - 4, 4), ""), "00\:00") + IF(TEXT(IF(ISNUMBER(SEARCH("-", F23:L23)), MID(F23:L23, SEARCH("-", F23:L23) + 1, 4), ""), "00\:00") < TEXT(IF(ISNUMBER(SEARCH("-", F23:L23)), MID(F23:L23, SEARCH("-", F23:L23) - 4, 4), ""), "00\:00"), 1, 0))*24,""))))/9.5} -> 3.8947368 | P23: =N23+O23 -> 3.8947368 | R23: =IF($C$4=1,SUM(P23+INDIRECT("'Week "&($B$3+1)&"'!P"&(ROW()))),IF($C$4=2,SUM(P23+INDIRECT("'Week "&($B$3-1)&"'!P"&(ROW()))))) -> 7.8947368 | S23: =(IFERROR(VLOOKUP(D23,'Employee Numbers'!$A$3:$C$84,3,FALSE),"NOT FOUND"))*8 -> 8 | U23: =COUNTIF(E23:K23,"0800-1730") -> 0 | V23: =COUNTIF(F23:L23,"1???-00?0") -> 1 | W23: =COUNTIF(F23:L23,"*0800-1730*CS*")+COUNTIF(F23:L23,"*0800-1730*DEMT*") -> 2 | Y23: =COUNTIF(K23:L23,"???0-*") -> 0
A24: Paediatric Emergency Consultant | D24: Dr Simon Craig | E24: =IFERROR(VLOOKUP(D24,'Employee Numbers'!$A$3:$B$83,2,FALSE),"NOT FOUND") -> 533509 | F24: SAB/L | G24: SAB/L | H24: SAB/L | I24: SAB/L | J24: SAB/L | K24: SAB/L | L24: SAB/L | N24: {=((SUM(IFERROR((TEXT(IF(ISNUMBER(SEARCH("-", F24:L24)), MID(F24:L24, SEARCH("-", F24:L24) + 1, 4), ""), "00\:00") - TEXT(IF(ISNUMBER(SEARCH("-", F24:L24)), MID(F24:L24, SEARCH("-", F24:L24) - 4, 4), ""), "00\:00") + IF(TEXT(IF(ISNUMBER(SEARCH("-", F24:L24)), MID(F24:L24, SEARCH("-", F24:L24) + 1, 4), ""), "00\:00") < TEXT(IF(ISNUMBER(SEARCH("-", F24:L24)), MID(F24:L24, SEARCH("-", F24:L24) - 4, 4), ""), "00\:00"), 1, 0))*24,""))))/9.5} -> 0 | P24: =N24+O24 -> 0 | R24: =IF($C$4=1,SUM(P24+INDIRECT("'Week "&($B$3+1)&"'!P"&(ROW()))),IF($C$4=2,SUM(P24+INDIRECT("'Week "&($B$3-1)&"'!P"&(ROW()))))) -> 0 | S24: =(IFERROR(VLOOKUP(D24,'Employee Numbers'!$A$3:$C$84,3,FALSE),"NOT FOUND"))*8 -> 0 | U24: =COUNTIF(E24:K24,"0800-1730") -> 0 | V24: =COUNTIF(F24:L24,"1???-00?0") -> 0 | W24: =COUNTIF(F24:L24,"*0800-1730*CS*")+COUNTIF(F24:L24,"*0800-1730*DEMT*") -> 0 | Y24: =COUNTIF(K24:L24,"???0-*") -> 0
A25: Paediatric Emergency Consultant | D25: Dr Celia Bagshaw | E25: =IFERROR(VLOOKUP(D25,'Employee Numbers'!$A$3:$B$83,2,FALSE),"NOT FOUND") -> 625985 | F25: 1430-0000 | G25: 0800-1730 CS | H25: 0800-1730 | I25: 1430-0000 | N25: {=((SUM(IFERROR((TEXT(IF(ISNUMBER(SEARCH("-", F25:L25)), MID(F25:L25, SEARCH("-", F25:L25) + 1, 4), ""), "00\:00") - TEXT(IF(ISNUMBER(SEARCH("-", F25:L25)), MID(F25:L25, SEARCH("-", F25:L25) - 4, 4), ""), "00\:00") + IF(TEXT(IF(ISNUMBER(SEARCH("-", F25:L25)), MID(F25:L25, SEARCH("-", F25:L25) + 1, 4), ""), "00\:00") < TEXT(IF(ISNUMBER(SEARCH("-", F25:L25)), MID(F25:L25, SEARCH("-", F25:L25) - 4, 4), ""), "00\:00"), 1, 0))*24,""))))/9.5} -> 4 | P25: =N25+O25 -> 4 | R25: =IF($C$4=1,SUM(P25+INDIRECT("'Week "&($B$3+1)&"'!P"&(ROW()))),IF($C$4=2,SUM(P25+INDIRECT("'Week "&($B$3-1)&"'!P"&(ROW()))))) -> 8 | S25: =(IFERROR(VLOOKUP(D25,'Employee Numbers'!$A$3:$C$84,3,FALSE),"NOT FOUND"))*8 -> 8 | U25: =COUNTIF(E25:K25,"0800-1730") -> 1 | V25: =COUNTIF(F25:L25,"1???-00?0") -> 2 | W25: =COUNTIF(F25:L25,"*0800-1730*CS*")+COUNTIF(F25:L25,"*0800-1730*DEMT*") -> 1 | Y25: =COUNTIF(K25:L25,"???0-*") -> 0
A26: Paediatric Emergency Consultant | D26: Dr Adnan Bilgrami | E26: =IFERROR(VLOOKUP(D26,'Employee Numbers'!$A$3:$B$83,2,FALSE),"NOT FOUND") -> 632301 | F26: 0800-1730 | G26: 1430-0000 | I26: 0800-1730 CS | J26: 0800-1730 | N26: {=((SUM(IFERROR((TEXT(IF(ISNUMBER(SEARCH("-", F26:L26)), MID(F26:L26, SEARCH("-", F26:L26) + 1, 4), ""), "00\:00") - TEXT(IF(ISNUMBER(SEARCH("-", F26:L26)), MID(F26:L26, SEARCH("-", F26:L26) - 4, 4), ""), "00\:00") + IF(TEXT(IF(ISNUMBER(SEARCH("-", F26:L26)), MID(F26:L26, SEARCH("-", F26:L26) + 1, 4), ""), "00\:00") < TEXT(IF(ISNUMBER(SEARCH("-", F26:L26)), MID(F26:L26, SEARCH("-", F26:L26) - 4, 4), ""), "00\:00"), 1, 0))*24,""))))/9.5} -> 4 | P26: =N26+O26 -> 4 | R26: =IF($C$4=1,SUM(P26+INDIRECT("'Week "&($B$3+1)&"'!P"&(ROW()))),IF($C$4=2,SUM(P26+INDIRECT("'Week "&($B$3-1)&"'!P"&(ROW()))))) -> 8 | S26: =(IFERROR(VLOOKUP(D26,'Employee Numbers'!$A$3:$C$84,3,FALSE),"NOT FOUND"))*8 -> 8 | U26: =COUNTIF(E26:K26,"0800-1730") -> 2 | V26: =COUNTIF(F26:L26,"1???-00?0") -> 1 | W26: =COUNTIF(F26:L26,"*0800-1730*CS*")+COUNTIF(F26:L26,"*0800-1730*DEMT*") -> 1 | Y26: =COUNTIF(K26:L26,"???0-*") -> 0
A27: Paediatric Emergency Consultant | D27: Dr Preeti Ramaswamy | E27: =IFERROR(VLOOKUP(D27,'Employee Numbers'!$A$3:$B$83,2,FALSE),"NOT FOUND") -> 613891 | F27: 1430-0000 | H27: 0800-1730 CS | K27: 1500-0030 | N27: {=((SUM(IFERROR((TEXT(IF(ISNUMBER(SEARCH("-", F27:L27)), MID(F27:L27, SEARCH("-", F27:L27) + 1, 4), ""), "00\:00") - TEXT(IF(ISNUMBER(SEARCH("-", F27:L27)), MID(F27:L27, SEARCH("-", F27:L27) - 4, 4), ""), "00\:00") + IF(TEXT(IF(ISNUMBER(SEARCH("-", F27:L27)), MID(F27:L27, SEARCH("-", F27:L27) + 1, 4), ""), "00\:00") < TEXT(IF(ISNUMBER(SEARCH("-", F27:L27)), MID(F27:L27, SEARCH("-", F27:L27) - 4, 4), ""), "00\:00"), 1, 0))*24,""))))/9.5} -> 3 | P27: =N27+O27 -> 3 | R27: =IF($C$4=1,SUM(P27+INDIRECT("'Week "&($B$3+1)&"'!P"&(ROW()))),IF($C$4=2,SUM(P27+INDIRECT("'Week "&($B$3-1)&"'!P"&(ROW()))))) -> 6 | S27: =(IFERROR(VLOOKUP(D27,'Employee Numbers'!$A$3:$C$84,3,FALSE),"NOT FOUND"))*8 -> 6 | U27: =COUNTIF(E27:K27,"0800-1730") -> 0 | V27: =COUNTIF(F27:L27,"1???-00?0") -> 2 | W27: =COUNTIF(F27:L27,"*0800-1730*CS*")+COUNTIF(F27:L27,"*0800-1730*DEMT*") -> 1 | Y27: =COUNTIF(K27:L27,"???0-*") -> 1
A28: Paediatric Emergency Consultant | D28: Dr Erin Mills | E28: =IFERROR(VLOOKUP(D28,'Employee Numbers'!$A$3:$B$83,2,FALSE),"NOT FOUND") -> 623657 | H28: 0800-1730 | N28: {=((SUM(IFERROR((TEXT(IF(ISNUMBER(SEARCH("-", F28:L28)), MID(F28:L28, SEARCH("-", F28:L28) + 1, 4), ""), "00\:00") - TEXT(IF(ISNUMBER(SEARCH("-", F28:L28)), MID(F28:L28, SEARCH("-", F28:L28) - 4, 4), ""), "00\:00") + IF(TEXT(IF(ISNUMBER(SEARCH("-", F28:L28)), MID(F28:L28, SEARCH("-", F28:L28) + 1, 4), ""), "00\:00") < TEXT(IF(ISNUMBER(SEARCH("-", F28:L28)), MID(F28:L28, SEARCH("-", F28:L28) - 4, 4), ""), "00\:00"), 1, 0))*24,""))))/9.5} -> 1 | P28: =N28+O28 -> 1 | R28: =IF($C$4=1,SUM(P28+INDIRECT("'Week "&($B$3+1)&"'!P"&(ROW()))),IF($C$4=2,SUM(P28+INDIRECT("'Week "&($B$3-1)&"'!P"&(ROW()))))) -> 2 | S28: =(IFERROR(VLOOKUP(D28,'Employee Numbers'!$A$3:$C$84,3,FALSE),"NOT FOUND"))*8 -> 2 | U28: =COUNTIF(E28:K28,"0800-1730") -> 1 | V28: =COUNTIF(F28:L28,"1???-00?0") -> 0 | W28: =COUNTIF(F28:L28,"*0800-1730*CS*")+COUNTIF(F28:L28,"*0800-1730*DEMT*") -> 0 | Y28: =COUNTIF(K28:L28,"???0-*") -> 0
A29: Paediatric Emergency Consultant | D29: Dr Stella Robinson | E29: =IFERROR(VLOOKUP(D29,'Employee Numbers'!$A$3:$B$83,2,FALSE),"NOT FOUND") -> 623708 | G29: 1430-0000 | H29: 0800-1730 CS | K29: 0800-1730 | N29: {=((SUM(IFERROR((TEXT(IF(ISNUMBER(SEARCH("-", F29:L29)), MID(F29:L29, SEARCH("-", F29:L29) + 1, 4), ""), "00\:00") - TEXT(IF(ISNUMBER(SEARCH("-", F29:L29)), MID(F29:L29, SEARCH("-", F29:L29) - 4, 4), ""), "00\:00") + IF(TEXT(IF(ISNUMBER(SEARCH("-", F29:L29)), MID(F29:L29, SEARCH("-", F29:L29) + 1, 4), ""), "00\:00") < TEXT(IF(ISNUMBER(SEARCH("-", F29:L29)), MID(F29:L29, SEARCH("-", F29:L29) - 4, 4), ""), "00\:00"), 1, 0))*24,""))))/9.5} -> 3 | P29: =N29+O29 -> 3 | R29: =IF($C$4=1,SUM(P29+INDIRECT("'Week "&($B$3+1)&"'!P"&(ROW()))),IF($C$4=2,SUM(P29+INDIRECT("'Week "&($B$3-1)&"'!P"&(ROW()))))) -> 6 | S29: =(IFERROR(VLOOKUP(D29,'Employee Numbers'!$A$3:$C$84,3,FALSE),"NOT FOUND"))*8 -> 6 | U29: =COUNTIF(E29:K29,"0800-1730") -> 1 | V29: =COUNTIF(F29:L29,"1???-00?0") -> 1 | W29: =COUNTIF(F29:L29,"*0800-1730*CS*")+COUNTIF(F29:L29,"*0800-1730*DEMT*") -> 1 | Y29: =COUNTIF(K29:L29,"???0-*") -> 1
A30: Paediatric Emergency Consultant | D30: Dr Bev Thompson | E30: =IFERROR(VLOOKUP(D30,'Employee Numbers'!$A$3:$B$83,2,FALSE),"NOT FOUND") -> 627680 | H30: 0800-1730 CS | I30: 0800-1730 | K30: 1500-0030 | N30: {=((SUM(IFERROR((TEXT(IF(ISNUMBER(SEARCH("-", F30:L30)), MID(F30:L30, SEARCH("-", F30:L30) + 1, 4), ""), "00\:00") - TEXT(IF(ISNUMBER(SEARCH("-", F30:L30)), MID(F30:L30, SEARCH("-", F30:L30) - 4, 4), ""), "00\:00") + IF(TEXT(IF(ISNUMBER(SEARCH("-", F30:L30)), MID(F30:L30, SEARCH("-", F30:L30) + 1, 4), ""), "00\:00") < TEXT(IF(ISNUMBER(SEARCH("-", F30:L30)), MID(F30:L30, SEARCH("-", F30:L30) - 4, 4), ""), "00\:00"), 1, 0))*24,""))))/9.5} -> 3 | P30: =N30+O30 -> 3 | R30: =IF($C$4=1,SUM(P30+INDIRECT("'Week "&($B$3+1)&"'!P"&(ROW()))),IF($C$4=2,SUM(P30+INDIRECT("'Week "&($B$3-1)&"'!P"&(ROW()))))) -> 6 | S30: =(IFERROR(VLOOKUP(D30,'Employee Numbers'!$A$3:$C$84,3,FALSE),"NOT FOUND"))*8 -> 6 | U30: =COUNTIF(E30:K30,"0800-1730") -> 1 | V30: =COUNTIF(F30:L30,"1???-00?0") -> 1 | W30: =COUNTIF(F30:L30,"*0800-1730*CS*")+COUNTIF(F30:L30,"*0800-1730*DEMT*") -> 1 | Y30: =COUNTIF(K30:L30,"???0-*") -> 1
A31: Paediatric Emergency Consultant | D31: Dr John Unwin | E31: =IFERROR(VLOOKUP(D31,'Employee Numbers'!$A$3:$B$83,2,FALSE),"NOT FOUND") -> 633210 | I31: 0800-1730 | J31: 0800-1730 | N31: {=((SUM(IFERROR((TEXT(IF(ISNUMBER(SEARCH("-", F31:L31)), MID(F31:L31, SEARCH("-", F31:L31) + 1, 4), ""), "00\:00") - TEXT(IF(ISNUMBER(SEARCH("-", F31:L31)), MID(F31:L31, SEARCH("-", F31:L31) - 4, 4), ""), "00\:00") + IF(TEXT(IF(ISNUMBER(SEARCH("-", F31:L31)), MID(F31:L31, SEARCH("-", F31:L31) + 1, 4), ""), "00\:00") < TEXT(IF(ISNUMBER(SEARCH("-", F31:L31)), MID(F31:L31, SEARCH("-", F31:L31) - 4, 4), ""), "00\:00"), 1, 0))*24,""))))/9.5} -> 2 | P31: =N31+O31 -> 2 | R31: =IF($C$4=1,SUM(P31+INDIRECT("'Week "&($B$3+1)&"'!P"&(ROW()))),IF($C$4=2,SUM(P31+INDIRECT("'Week "&($B$3-1)&"'!P"&(ROW()))))) -> 6 | S31: =(IFERROR(VLOOKUP(D31,'Employee Numbers'!$A$3:$C$84,3,FALSE),"NOT FOUND"))*8 -> 6 | U31: =COUNTIF(E31:K31,"0800-1730") -> 2 | V31: =COUNTIF(F31:L31,"1???-00?0") -> 0 | W31: =COUNTIF(F31:L31,"*0800-1730*CS*")+COUNTIF(F31:L31,"*0800-1730*DEMT*") -> 0 | Y31: =COUNTIF(K31:L31,"???0-*") -> 0
A32: Paediatric Emergency Consultant | D32: Dr Siri Samudrala | E32: =IFERROR(VLOOKUP(D32,'Employee Numbers'!$A$3:$B$83,2,FALSE),"NOT FOUND") -> 618952 | F32: AL | G32: AL | H32: AL | I32: AL | J32: AL | K32: AL | L32: AL | N32: {=((SUM(IFERROR((TEXT(IF(ISNUMBER(SEARCH("-", F32:L32)), MID(F32:L32, SEARCH("-", F32:L32) + 1, 4), ""), "00\:00") - TEXT(IF(ISNUMBER(SEARCH("-", F32:L32)), MID(F32:L32, SEARCH("-", F32:L32) - 4, 4), ""), "00\:00") + IF(TEXT(IF(ISNUMBER(SEARCH("-", F32:L32)), MID(F32:L32, SEARCH("-", F32:L32) + 1, 4), ""), "00\:00") < TEXT(IF(ISNUMBER(SEARCH("-", F32:L32)), MID(F32:L32, SEARCH("-", F32:L32) - 4, 4), ""), "00\:00"), 1, 0))*24,""))))/9.5} -> 0 | P32: =N32+O32 -> 0 | R32: =IF($C$4=1,SUM(P32+INDIRECT("'Week "&($B$3+1)&"'!P"&(ROW()))),IF($C$4=2,SUM(P32+INDIRECT("'Week "&($B$3-1)&"'!P"&(ROW()))))) -> 3 | S32: =(IFERROR(VLOOKUP(D32,'Employee Numbers'!$A$3:$C$84,3,FALSE),"NOT FOUND"))*8 -> 6 | U32: =COUNTIF(E32:K32,"0800-1730") -> 0 | V32: =COUNTIF(F32:L32,"1???-00?0") -> 0 | W32: =COUNTIF(F32:L32,"*0800-1730*CS*")+COUNTIF(F32:L32,"*0800-1730*DEMT*") -> 0 | Y32: =COUNTIF(K32:L32,"???0-*") -> 0
A33: Paediatric Emergency Consultant | D33: Dr Tessa Smith | E33: =IFERROR(VLOOKUP(D33,'Employee Numbers'!$A$3:$B$83,2,FALSE),"NOT FOUND") -> 649039 | F33: 0800-1730 | H33: 0800-1730 CS | L33: 1500-0030 | N33: {=((SUM(IFERROR((TEXT(IF(ISNUMBER(SEARCH("-", F33:L33)), MID(F33:L33, SEARCH("-", F33:L33) + 1, 4), ""), "00\:00") - TEXT(IF(ISNUMBER(SEARCH("-", F33:L33)), MID(F33:L33, SEARCH("-", F33:L33) - 4, 4), ""), "00\:00") + IF(TEXT(IF(ISNUMBER(SEARCH("-", F33:L33)), MID(F33:L33, SEARCH("-", F33:L33) + 1, 4), ""), "00\:00") < TEXT(IF(ISNUMBER(SEARCH("-", F33:L33)), MID(F33:L33, SEARCH("-", F33:L33) - 4, 4), ""), "00\:00"), 1, 0))*24,""))))/9.5} -> 3 | P33: =N33+O33 -> 3 | R33: =IF($C$4=1,SUM(P33+INDIRECT("'Week "&($B$3+1)&"'!P"&(ROW()))),IF($C$4=2,SUM(P33+INDIRECT("'Week "&($B$3-1)&"'!P"&(ROW()))))) -> 5 | S33: =(IFERROR(VLOOKUP(D33,'Employee Numbers'!$A$3:$C$84,3,FALSE),"NOT FOUND"))*8 -> 5 | U33: =COUNTIF(E33:K33,"0800-1730") -> 1 | V33: =COUNTIF(F33:L33,"1???-00?0") -> 1 | W33: =COUNTIF(F33:L33,"*0800-1730*CS*")+COUNTIF(F33:L33,"*0800-1730*DEMT*") -> 1 | Y33: =COUNTIF(K33:L33,"???0-*") -> 1
A34: Paediatric Emergency Consultant | D34: Dr Brad Dent | E34: =IFERROR(VLOOKUP(D34,'Employee Numbers'!$A$3:$B$83,2,FALSE),"NOT FOUND") -> 649671 | F34: 0800-1730 OCS | G34: 0800-1730 | I34: 1430-0000 | N34: {=((SUM(IFERROR((TEXT(IF(ISNUMBER(SEARCH("-", F34:L34)), MID(F34:L34, SEARCH("-", F34:L34) + 1, 4), ""), "00\:00") - TEXT(IF(ISNUMBER(SEARCH("-", F34:L34)), MID(F34:L34, SEARCH("-", F34:L34) - 4, 4), ""), "00\:00") + IF(TEXT(IF(ISNUMBER(SEARCH("-", F34:L34)), MID(F34:L34, SEARCH("-", F34:L34) + 1, 4), ""), "00\:00") < TEXT(IF(ISNUMBER(SEARCH("-", F34:L34)), MID(F34:L34, SEARCH("-", F34:L34) - 4, 4), ""), "00\:00"), 1, 0))*24,""))))/9.5} -> 3 | P34: =N34+O34 -> 3 | R34: =IF($C$4=1,SUM(P34+INDIRECT("'Week "&($B$3+1)&"'!P"&(ROW()))),IF($C$4=2,SUM(P34+INDIRECT("'Week "&($B$3-1)&"'!P"&(ROW()))))) -> 6 | S34: =(IFERROR(VLOOKUP(D34,'Employee Numbers'!$A$3:$C$84,3,FALSE),"NOT FOUND"))*8 -> 6 | U34: =COUNTIF(E34:K34,"0800-1730") -> 1 | V34: =COUNTIF(F34:L34,"1???-00?0") -> 1 | W34: =COUNTIF(F34:L34,"*0800-1730*CS*")+COUNTIF(F34:L34,"*0800-1730*DEMT*") -> 1 | Y34: =COUNTIF(K34:L34,"???0-*") -> 0
A35: Paediatric Emergency Consultant | D35: Dr Marjolein Slaa | E35: =IFERROR(VLOOKUP(D35,'Employee Numbers'!$A$3:$B$83,2,FALSE),"NOT FOUND") -> 646047 | H35: 0800-1730 OCS | I35: S/L AM | J35: 1430-0000 | N35: {=((SUM(IFERROR((TEXT(IF(ISNUMBER(SEARCH("-", F35:L35)), MID(F35:L35, SEARCH("-", F35:L35) + 1, 4), ""), "00\:00") - TEXT(IF(ISNUMBER(SEARCH("-", F35:L35)), MID(F35:L35, SEARCH("-", F35:L35) - 4, 4), ""), "00\:00") + IF(TEXT(IF(ISNUMBER(SEARCH("-", F35:L35)), MID(F35:L35, SEARCH("-", F35:L35) + 1, 4), ""), "00\:00") < TEXT(IF(ISNUMBER(SEARCH("-", F35:L35)), MID(F35:L35, SEARCH("-", F35:L35) - 4, 4), ""), "00\:00"), 1, 0))*24,""))))/9.5} -> 2 | P35: =N35+O35 -> 2 | R35: =IF($C$4=1,SUM(P35+INDIRECT("'Week "&($B$3+1)&"'!P"&(ROW()))),IF($C$4=2,SUM(P35+INDIRECT("'Week "&($B$3-1)&"'!P"&(ROW()))))) -> 4 | S35: =(IFERROR(VLOOKUP(D35,'Employee Numbers'!$A$3:$C$84,3,FALSE),"NOT FOUND"))*8 -> 5 | U35: =COUNTIF(E35:K35,"0800-1730") -> 0 | V35: =COUNTIF(F35:L35,"1???-00?0") -> 1 | W35: =COUNTIF(F35:L35,"*0800-1730*CS*")+COUNTIF(F35:L35,"*0800-1730*DEMT*") -> 1 | Y35: =COUNTIF(K35:L35,"???0-*") -> 0
A36: Paediatric Emergency Consultant | D36: Dr Natalie Hood | E36: =IFERROR(VLOOKUP(D36,'Employee Numbers'!$A$3:$B$83,2,FALSE),"NOT FOUND") -> 164003 | F36: 1430-0000 | H36: 0800-1730 CS | N36: {=((SUM(IFERROR((TEXT(IF(ISNUMBER(SEARCH("-", F36:L36)), MID(F36:L36, SEARCH("-", F36:L36) + 1, 4), ""), "00\:00") - TEXT(IF(ISNUMBER(SEARCH("-", F36:L36)), MID(F36:L36, SEARCH("-", F36:L36) - 4, 4), ""), "00\:00") + IF(TEXT(IF(ISNUMBER(SEARCH("-", F36:L36)), MID(F36:L36, SEARCH("-", F36:L36) + 1, 4), ""), "00\:00") < TEXT(IF(ISNUMBER(SEARCH("-", F36:L36)), MID(F36:L36, SEARCH("-", F36:L36) - 4, 4), ""), "00\:00"), 1, 0))*24,""))))/9.5} -> 2 | P36: =N36+O36 -> 2 | R36: =IF($C$4=1,SUM(P36+INDIRECT("'Week "&($B$3+1)&"'!P"&(ROW()))),IF($C$4=2,SUM(P36+INDIRECT("'Week "&($B$3-1)&"'!P"&(ROW()))))) -> 4 | S36: =(IFERROR(VLOOKUP(D36,'Employee Numbers'!$A$3:$C$84,3,FALSE),"NOT FOUND"))*8 -> 4 | U36: =COUNTIF(E36:K36,"0800-1730") -> 0 | V36: =COUNTIF(F36:L36,"1???-00?0") -> 1 | W36: =COUNTIF(F36:L36,"*0800-1730*CS*")+COUNTIF(F36:L36,"*0800-1730*DEMT*") -> 1 | Y36: =COUNTIF(K36:L36,"???0-*") -> 0
A37: Paediatric Emergency Consultant | D37: Dr Michael Coman | E37: =IFERROR(VLOOKUP(D37,'Employee Numbers'!$A$3:$B$83,2,FALSE),"NOT FOUND") -> 609408 | G37: 0800-1730 | H37: 0800-1730 CS | I37: 1430-0000 | J37: 1430-0000 | N37: {=((SUM(IFERROR((TEXT(IF(ISNUMBER(SEARCH("-", F37:L37)), MID(F37:L37, SEARCH("-", F37:L37) + 1, 4), ""), "00\:00") - TEXT(IF(ISNUMBER(SEARCH("-", F37:L37)), MID(F37:L37, SEARCH("-", F37:L37) - 4, 4), ""), "00\:00") + IF(TEXT(IF(ISNUMBER(SEARCH("-", F37:L37)), MID(F37:L37, SEARCH("-", F37:L37) + 1, 4), ""), "00\:00") < TEXT(IF(ISNUMBER(SEARCH("-", F37:L37)), MID(F37:L37, SEARCH("-", F37:L37) - 4, 4), ""), "00\:00"), 1, 0))*24,""))))/9.5} -> 4 | P37: =N37+O37 -> 4 | R37: =IF($C$4=1,SUM(P37+INDIRECT("'Week "&($B$3+1)&"'!P"&(ROW()))),IF($C$4=2,SUM(P37+INDIRECT("'Week "&($B$3-1)&"'!P"&(ROW()))))) -> 4 | S37: =(IFERROR(VLOOKUP(D37,'Employee Numbers'!$A$3:$C$84,3,FALSE),"NOT FOUND"))*8 -> 4 | U37: =COUNTIF(E37:K37,"0800-1730") -> 1 | V37: =COUNTIF(F37:L37,"1???-00?0") -> 2 | W37: =COUNTIF(F37:L37,"*0800-1730*CS*")+COUNTIF(F37:L37,"*0800-1730*DEMT*") -> 1 | Y37: =COUNTIF(K37:L37,"???0-*") -> 0
A38: Paediatric Emergency Consultant | D38: Dr Andrew Hardy | E38: =IFERROR(VLOOKUP(D38,'Employee Numbers'!$A$3:$B$83,2,FALSE),"NOT FOUND") -> 627619 | F38: CME/L | G38: CME/L | H38: CME/L | I38: CME/L | J38: CME/L | K38: CME/L | L38: ME/L | N38: {=((SUM(IFERROR((TEXT(IF(ISNUMBER(SEARCH("-", F38:L38)), MID(F38:L38, SEARCH("-", F38:L38) + 1, 4), ""), "00\:00") - TEXT(IF(ISNUMBER(SEARCH("-", F38:L38)), MID(F38:L38, SEARCH("-", F38:L38) - 4, 4), ""), "00\:00") + IF(TEXT(IF(ISNUMBER(SEARCH("-", F38:L38)), MID(F38:L38, SEARCH("-", F38:L38) + 1, 4), ""), "00\:00") < TEXT(IF(ISNUMBER(SEARCH("-", F38:L38)), MID(F38:L38, SEARCH("-", F38:L38) - 4, 4), ""), "00\:00"), 1, 0))*24,""))))/9.5} -> 0 | O38: 2 | P38: =N38+O38 -> 2 | R38: =IF($C$4=1,SUM(P38+INDIRECT("'Week "&($B$3+1)&"'!P"&(ROW()))),IF($C$4=2,SUM(P38+INDIRECT("'Week "&($B$3-1)&"'!P"&(ROW()))))) -> 4 | S38: =(IFERROR(VLOOKUP(D38,'Employee Numbers'!$A$3:$C$84,3,FALSE),"NOT FOUND"))*8 -> 4 | U38: =COUNTIF(E38:K38,"0800-1730") -> 0 | V38: =COUNTIF(F38:L38,"1???-00?0") -> 0 | W38: =COUNTIF(F38:L38,"*0800-1730*CS*")+COUNTIF(F38:L38,"*0800-1730*DEMT*") -> 0 | Y38: =COUNTIF(K38:L38,"???0-*") -> 0
A39: Paediatric Emergency Consultant | D39: Dr Gargi Kanabar | E39: =IFERROR(VLOOKUP(D39,'Employee Numbers'!$A$3:$B$83,2,FALSE),"NOT FOUND") -> 632646 | F39: 0800-1730 CS | H39: 0800-1730 | J39: 0800-1730 | L39: 1500-0030 | N39: {=((SUM(IFERROR((TEXT(IF(ISNUMBER(SEARCH("-", F39:L39)), MID(F39:L39, SEARCH("-", F39:L39) + 1, 4), ""), "00\:00") - TEXT(IF(ISNUMBER(SEARCH("-", F39:L39)), MID(F39:L39, SEARCH("-", F39:L39) - 4, 4), ""), "00\:00") + IF(TEXT(IF(ISNUMBER(SEARCH("-", F39:L39)), MID(F39:L39, SEARCH("-", F39:L39) + 1, 4), ""), "00\:00") < TEXT(IF(ISNUMBER(SEARCH("-", F39:L39)), MID(F39:L39, SEARCH("-", F39:L39) - 4, 4), ""), "00\:00"), 1, 0))*24,""))))/9.5} -> 4 | P39: =N39+O39 -> 4 | R39: =IF($C$4=1,SUM(P39+INDIRECT("'Week "&($B$3+1)&"'!P"&(ROW()))),IF($C$4=2,SUM(P39+INDIRECT("'Week "&($B$3-1)&"'!P"&(ROW()))))) -> 4 | S39: =(IFERROR(VLOOKUP(D39,'Employee Numbers'!$A$3:$C$84,3,FALSE),"NOT FOUND"))*8 -> 4 | U39: =COUNTIF(E39:K39,"0800-1730") -> 2 | V39: =COUNTIF(F39:L39,"1???-00?0") -> 1 | W39: =COUNTIF(F39:L39,"*0800-1730*CS*")+COUNTIF(F39:L39,"*0800-1730*DEMT*") -> 1 | Y39: =COUNTIF(K39:L39,"???0-*") -> 1
A40: Paediatric Emergency Consultant | D40: Dr Mandy Parr | E40: =IFERROR(VLOOKUP(D40,'Employee Numbers'!$A$3:$B$83,2,FALSE),"NOT FOUND") -> 652844 | N40: {=((SUM(IFERROR((TEXT(IF(ISNUMBER(SEARCH("-", F40:L40)), MID(F40:L40, SEARCH("-", F40:L40) + 1, 4), ""), "00\:00") - TEXT(IF(ISNUMBER(SEARCH("-", F40:L40)), MID(F40:L40, SEARCH("-", F40:L40) - 4, 4), ""), "00\:00") + IF(TEXT(IF(ISNUMBER(SEARCH("-", F40:L40)), MID(F40:L40, SEARCH("-", F40:L40) + 1, 4), ""), "00\:00") < TEXT(IF(ISNUMBER(SEARCH("-", F40:L40)), MID(F40:L40, SEARCH("-", F40:L40) - 4, 4), ""), "00\:00"), 1, 0))*24,""))))/9.5} -> 0 | P40: =N40+O40 -> 0 | R40: =IF($C$4=1,SUM(P40+INDIRECT("'Week "&($B$3+1)&"'!P"&(ROW()))),IF($C$4=2,SUM(P40+INDIRECT("'Week "&($B$3-1)&"'!P"&(ROW()))))) -> 4 | S40: =(IFERROR(VLOOKUP(D40,'Employee Numbers'!$A$3:$C$84,3,FALSE),"NOT FOUND"))*8 -> 4 | U40: =COUNTIF(E40:K40,"0800-1730") -> 0 | V40: =COUNTIF(F40:L40,"1???-00?0") -> 0 | W40: =COUNTIF(F40:L40,"*0800-1730*CS*")+COUNTIF(F40:L40,"*0800-1730*DEMT*") -> 0 | Y40: =COUNTIF(K40:L40,"???0-*") -> 0
A41: Paediatric Emergency Consultant | D41: Dr Tecwyn Davies | E41: =IFERROR(VLOOKUP(D41,'Employee Numbers'!$A$3:$B$83,2,FALSE),"NOT FOUND") -> 634491 | N41: {=((SUM(IFERROR((TEXT(IF(ISNUMBER(SEARCH("-", F41:L41)), MID(F41:L41, SEARCH("-", F41:L41) + 1, 4), ""), "00\:00") - TEXT(IF(ISNUMBER(SEARCH("-", F41:L41)), MID(F41:L41, SEARCH("-", F41:L41) - 4, 4), ""), "00\:00") + IF(TEXT(IF(ISNUMBER(SEARCH("-", F41:L41)), MID(F41:L41, SEARCH("-", F41:L41) + 1, 4), ""), "00\:00") < TEXT(IF(ISNUMBER(SEARCH("-", F41:L41)), MID(F41:L41, SEARCH("-", F41:L41) - 4, 4), ""), "00\:00"), 1, 0))*24,""))))/9.5} -> 0 | P41: =N41+O41 -> 0 | R41: =IF($C$4=1,SUM(P41+INDIRECT("'Week "&($B$3+1)&"'!P"&(ROW()))),IF($C$4=2,SUM(P41+INDIRECT("'Week "&($B$3-1)&"'!P"&(ROW()))))) -> 4 | S41: =(IFERROR(VLOOKUP(D41,'Employee Numbers'!$A$3:$C$84,3,FALSE),"NOT FOUND"))*8 -> 4 | U41: =COUNTIF(E41:K41,"0800-1730") -> 0 | V41: =COUNTIF(F41:L41,"1???-00?0") -> 0 | W41: =COUNTIF(F41:L41,"*0800-1730*CS*")+COUNTIF(F41:L41,"*0800-1730*DEMT*") -> 0 | Y41: =COUNTIF(K41:L41,"???0-*") -> 0
A42: Paediatric Emergency Consultant | D42: Dr Patrick Finn | E42: =IFERROR(VLOOKUP(D42,'Employee Numbers'!$A$3:$B$83,2,FALSE),"NOT FOUND") -> 621988 | F42: PAT/L | G42: PAT/L | H42: PAT/L | I42: PAT/L | J42: PAT/L | K42: PAT/L | L42: PAT/L | N42: {=((SUM(IFERROR((TEXT(IF(ISNUMBER(SEARCH("-", F42:L42)), MID(F42:L42, SEARCH("-", F42:L42) + 1, 4), ""), "00\:00") - TEXT(IF(ISNUMBER(SEARCH("-", F42:L42)), MID(F42:L42, SEARCH("-", F42:L42) - 4, 4), ""), "00\:00") + IF(TEXT(IF(ISNUMBER(SEARCH("-", F42:L42)), MID(F42:L42, SEARCH("-", F42:L42) + 1, 4), ""), "00\:00") < TEXT(IF(ISNUMBER(SEARCH("-", F42:L42)), MID(F42:L42, SEARCH("-", F42:L42) - 4, 4), ""), "00\:00"), 1, 0))*24,""))))/9.5} -> 0 | O42: 2 | P42: =N42+O42 -> 2 | R42: =IF($C$4=1,SUM(P42+INDIRECT("'Week "&($B$3+1)&"'!P"&(ROW()))),IF($C$4=2,SUM(P42+INDIRECT("'Week "&($B$3-1)&"'!P"&(ROW()))))) -> 4 | S42: =(IFERROR(VLOOKUP(D42,'Employee Numbers'!$A$3:$C$84,3,FALSE),"NOT FOUND"))*8 -> 4 | U42: =COUNTIF(E42:K42,"0800-1730") -> 0 | V42: =COUNTIF(F42:L42,"1???-00?0") -> 0 | W42: =COUNTIF(F42:L42,"*0800-1730*CS*")+COUNTIF(F42:L42,"*0800-1730*DEMT*") -> 0 | Y42: =COUNTIF(K42:L42,"???0-*") -> 0
A43: Paediatric Emergency Consultant | D43: Dr Chris Fong | E43: =IFERROR(VLOOKUP(D43,'Employee Numbers'!$A$3:$B$83,2,FALSE),"NOT FOUND") -> 409677 | I43: 0800-1730 OCS | N43: {=((SUM(IFERROR((TEXT(IF(ISNUMBER(SEARCH("-", F43:L43)), MID(F43:L43, SEARCH("-", F43:L43) + 1, 4), ""), "00\:00") - TEXT(IF(ISNUMBER(SEARCH("-", F43:L43)), MID(F43:L43, SEARCH("-", F43:L43) - 4, 4), ""), "00\:00") + IF(TEXT(IF(ISNUMBER(SEARCH("-", F43:L43)), MID(F43:L43, SEARCH("-", F43:L43) + 1, 4), ""), "00\:00") < TEXT(IF(ISNUMBER(SEARCH("-", F43:L43)), MID(F43:L43, SEARCH("-", F43:L43) - 4, 4), ""), "00\:00"), 1, 0))*24,""))))/9.5} -> 1 | P43: =N43+O43 -> 1 | R43: =IF($C$4=1,SUM(P43+INDIRECT("'Week "&($B$3+1)&"'!P"&(ROW()))),IF($C$4=2,SUM(P43+INDIRECT("'Week "&($B$3-1)&"'!P"&(ROW()))))) -> 3 | S43: =(IFERROR(VLOOKUP(D43,'Employee Numbers'!$A$3:$C$84,3,FALSE),"NOT FOUND"))*8 -> 3 | U43: =COUNTIF(E43:K43,"0800-1730") -> 0 | V43: =COUNTIF(F43:L43,"1???-00?0") -> 0 | W43: =COUNTIF(F43:L43,"*0800-1730*CS*")+COUNTIF(F43:L43,"*0800-1730*DEMT*") -> 1 | Y43: =COUNTIF(K43:L43,"???0-*") -> 0
A44: Paediatric Emergency Consultant | D44: Dr Matthew Tang | E44: =IFERROR(VLOOKUP(D44,'Employee Numbers'!$A$3:$B$83,2,FALSE),"NOT FOUND") -> 632590 | F44: 0800-1730 | G44: 0800-1730 | H44: 1430-0000 | I44: 0800-1730 OCS | N44: {=((SUM(IFERROR((TEXT(IF(ISNUMBER(SEARCH("-", F44:L44)), MID(F44:L44, SEARCH("-", F44:L44) + 1, 4), ""), "00\:00") - TEXT(IF(ISNUMBER(SEARCH("-", F44:L44)), MID(F44:L44, SEARCH("-", F44:L44) - 4, 4), ""), "00\:00") + IF(TEXT(IF(ISNUMBER(SEARCH("-", F44:L44)), MID(F44:L44, SEARCH("-", F44:L44) + 1, 4), ""), "00\:00") < TEXT(IF(ISNUMBER(SEARCH("-", F44:L44)), MID(F44:L44, SEARCH("-", F44:L44) - 4, 4), ""), "00\:00"), 1, 0))*24,""))))/9.5} -> 4 | P44: =N44+O44 -> 4 | R44: =IF($C$4=1,SUM(P44+INDIRECT("'Week "&($B$3+1)&"'!P"&(ROW()))),IF($C$4=2,SUM(P44+INDIRECT("'Week "&($B$3-1)&"'!P"&(ROW()))))) -> 4 | S44: =(IFERROR(VLOOKUP(D44,'Employee Numbers'!$A$3:$C$84,3,FALSE),"NOT FOUND"))*8 -> 4 | U44: =COUNTIF(E44:K44,"0800-1730") -> 2 | V44: =COUNTIF(F44:L44,"1???-00?0") -> 1 | W44: =COUNTIF(F44:L44,"*0800-1730*CS*")+COUNTIF(F44:L44,"*0800-1730*DEMT*") -> 1 | Y44: =COUNTIF(K44:L44,"???0-*") -> 0
...

Sheet Week 2
A1: Role (uploaded) | B1: Pager No (uploaded) | C1: Cost Centre (Not Used) | D1: Name (Not Used) | E1: Emp No | F1: Monday | G1: Tuesday | H1: Wednesday | I1: Thursday | J1: Friday | K1: Saturday | L1: Sunday | M1: ONCALL Workrule Code
A2: Date | F2: ='Week 1'!F2+7 -> 46153 | G2: =F2+1 -> 46154 | H2: =G2+1 -> 46155 | I2: =H2+1 -> 46156 | J2: =I2+1 -> 46157 | K2: =J2+1 -> 46158 | L2: =K2+1 -> 46159
A3: Week | B3: =1+(F2-'Week 1'!F2)/7 -> 2
A4: PAY PERIOD WEEK | C4: =IF(INDIRECT("'Week "&(B3-1)&"'!C4")=1,2,IF(INDIRECT("'Week "&(B3-1)&"'!C4")=2,1,_xludf.NA)) -> 2 | D4: ='Week 1'!D4:L4 -> PAEDIATRIC EMERGENCY DEPARTMENT ROSTER - Term 2 2026
D6: AM SMS | F6: =COUNTIF(F$21:F$49,"0800-1???")-COUNTIFS(F$48,"0800-1???",$D$48,"Locum")-COUNTIFS(F$49,"0800-1???",$D$49,"Locum") -> 3 | G6: =COUNTIF(G$21:G$49,"0800-1???")-COUNTIFS(G$48,"0800-1???",$D$48,"Locum")-COUNTIFS(G$49,"0800-1???",$D$49,"Locum") -> 3 | H6: =COUNTIF(H$21:H$49,"0800-1???")-COUNTIFS(H$48,"0800-1???",$D$48,"Locum")-COUNTIFS(H$49,"0800-1???",$D$49,"Locum") -> 3 | I6: =COUNTIF(I$21:I$49,"0800-1???")-COUNTIFS(I$48,"0800-1???",$D$48,"Locum")-COUNTIFS(I$49,"0800-1???",$D$49,"Locum") -> 3 | J6: =COUNTIF(J$21:J$49,"0800-1???")-COUNTIFS(J$48,"0800-1???",$D$48,"Locum")-COUNTIFS(J$49,"0800-1???",$D$49,"Locum") -> 3 | K6: =COUNTIF(K$21:K$49,"0800-1???")-COUNTIFS(K$48,"0800-1???",$D$48,"Locum")-COUNTIFS(K$49,"0800-1???",$D$49,"Locum") -> 2 | L6: =COUNTIF(L$21:L$49,"0800-1???")-COUNTIFS(L$48,"0800-1???",$D$48,"Locum")-COUNTIFS(L$49,"0800-1???",$D$49,"Locum") -> 2
D7: AM JMS | F7: =COUNTIF(F$54:F$102,"0800-1???") -> 6 | G7: =COUNTIF(G$54:G$102,"0800-1???") -> 7 | H7: =COUNTIF(H$54:H$102,"0800-1???") -> 5 | I7: =COUNTIF(I$54:I$102,"0800-1???") -> 4 | J7: =COUNTIF(J$54:J$102,"0800-1???") -> 4 | K7: =COUNTIF(K$54:K$102,"0800-1???") -> 5 | L7: =COUNTIF(L$54:L$102,"0800-1???") -> 6
D8: AM Total | F8: =F6+F7 -> 9 | G8: =G6+G7 -> 10 | H8: =H6+H7 -> 8 | I8: =I6+I7 -> 7 | J8: =J6+J7 -> 7 | K8: =K6+K7 -> 7 | L8: =L6+L7 -> 8
D10: SMS Swing | F10: =COUNTIF(F$21:F$49,"1100-????")-COUNTIFS(F$48,"1100-????",$D$48,"Locum")-COUNTIFS(F$49,"1100-????",$D$49,"Locum") -> 0 | G10: =COUNTIF(G$21:G$49,"1100-????")-COUNTIFS(G$48,"1100-????",$D$48,"Locum")-COUNTIFS(G$49,"1100-????",$D$49,"Locum") -> 0 | H10: =COUNTIF(H$21:H$49,"1100-????")-COUNTIFS(H$48,"1100-????",$D$48,"Locum")-COUNTIFS(H$49,"1100-????",$D$49,"Locum") -> 0 | I10: =COUNTIF(I$21:I$49,"1100-????")-COUNTIFS(I$48,"1100-????",$D$48,"Locum")-COUNTIFS(I$49,"1100-????",$D$49,"Locum") -> 0 | J10: =COUNTIF(J$21:J$49,"1100-????")-COUNTIFS(J$48,"1100-????",$D$48,"Locum")-COUNTIFS(J$49,"1100-????",$D$49,"Locum") -> 0 | K10: =COUNTIF(K$21:K$49,"1100-????")-COUNTIFS(K$48,"1100-????",$D$48,"Locum")-COUNTIFS(K$49,"1100-????",$D$49,"Locum") -> 0 | L10: =COUNTIF(L$21:L$49,"1100-????")-COUNTIFS(L$48,"1100-????",$D$48,"Locum")-COUNTIFS(L$49,"1100-????",$D$49,"Locum") -> 0
D11: JMS Swing | F11: =COUNTIF(F$54:F$102,"1100-????") -> 0 | G11: =COUNTIF(G$54:G$102,"1100-????") -> 0 | H11: =COUNTIF(H$54:H$102,"1100-????") -> 0 | I11: =COUNTIF(I$54:I$102,"1100-????") -> 0 | J11: =COUNTIF(J$54:J$102,"1100-????") -> 0 | K11: =COUNTIF(K$54:K$102,"1100-????") -> 0 | L11: =COUNTIF(L$54:L$102,"1100-????") -> 1
D12: PM SMS | F12: =COUNTIF(F$21:F$49,"1???-00?0")-COUNTIFS(F$48,"1???-00?0",$D$48,"Locum")-COUNTIFS(F$49,"1???-00?0",$D$49,"Locum") -> 3 | G12: =COUNTIF(G$21:G$49,"1???-00?0")-COUNTIFS(G$48,"1???-00?0",$D$48,"Locum")-COUNTIFS(G$49,"1???-00?0",$D$49,"Locum") -> 3 | H12: =COUNTIF(H$21:H$49,"1???-00?0")-COUNTIFS(H$48,"1???-00?0",$D$48,"Locum")-COUNTIFS(H$49,"1???-00?0",$D$49,"Locum") -> 3 | I12: =COUNTIF(I$21:I$49,"1???-00?0")-COUNTIFS(I$48,"1???-00?0",$D$48,"Locum")-COUNTIFS(I$49,"1???-00?0",$D$49,"Locum") -> 3 | J12: =COUNTIF(J$21:J$49,"1???-00?0")-COUNTIFS(J$48,"1???-00?0",$D$48,"Locum")-COUNTIFS(J$49,"1???-00?0",$D$49,"Locum") -> 3 | K12: =COUNTIF(K$21:K$49,"1???-00?0")-COUNTIFS(K$48,"1???-00?0",$D$48,"Locum")-COUNTIFS(K$49,"1???-00?0",$D$49,"Locum") -> 2 | L12: =COUNTIF(L$21:L$49,"1???-00?0")-COUNTIFS(L$48,"1???-00?0",$D$48,"Locum")-COUNTIFS(L$49,"1???-00?0",$D$49,"Locum") -> 2
D13: PM JMS | F13: =COUNTIF(F$54:F$102,"1???-0000*") -> 10 | G13: =COUNTIF(G$54:G$102,"1???-0000*") -> 9 | H13: =COUNTIF(H$54:H$102,"1???-0000*") -> 8 | I13: =COUNTIF(I$54:I$102,"1???-0000*") -> 8 | J13: =COUNTIF(J$54:J$102,"1???-0000*") -> 7 | K13: =COUNTIF(K$54:K$102,"1???-0000*") -> 7 | L13: =COUNTIF(L$54:L$102,"1???-0000*") -> 9
D14: PM Total | F14: =F12+F13 -> 13 | G14: =G12+G13 -> 12 | H14: =H12+H13 -> 11 | I14: =I12+I13 -> 11 | J14: =J12+J13 -> 10 | K14: =K12+K13 -> 9 | L14: =L12+L13 -> 11
D16: Night | F16: =COUNTIF(F$54:F$99,"2300-0830") -> 4 | G16: =COUNTIF(G$54:G$99,"2300-0830") -> 4 | H16: =COUNTIF(H$54:H$99,"2300-0830") -> 5 | I16: =COUNTIF(I$54:I$99,"2300-0830") -> 5 | J16: =COUNTIF(J$54:J$99,"2300-0830") -> 4 | K16: =COUNTIF(K$54:K$99,"2300-0830") -> 4 | L16: =COUNTIF(L$54:L$99,"2300-0830") -> 4
D18: Name | E18: Emp No | F18: Monday | G18: Tuesday | H18: Wednesday | I18: Thursday | J18: Friday | K18: Saturday | L18: Sunday | N18: Weekly | O18: Leave | P18: Total | R18: PP | S18: PP Contracted
F19: =F2 -> 46153 | G19: =F19+1 -> 46154 | H19: =G19+1 -> 46155 | I19: =H19+1 -> 46156 | J19: =I19+1 -> 46157 | K19: =J19+1 -> 46158 | L19: =K19+1 -> 46159 | N19: (shifts) | O19: (shifts) | R19: (shifts) | S19: (shifts) | U19: AM | V19: PM | W19: CS | X19: Swing | Y19: Weekend
A20: Staff Specialist | D20: Staff Specialist
A21: Paediatric Emergency Consultant | D21: Dr Adam West | E21: =IFERROR(VLOOKUP(D21,'Employee Numbers'!$A$3:$B$84,2,FALSE),"NOT FOUND") -> 287628 | F21: 0800-1730 CS | G21: 0800-1730 CS | H21: 0800-1730 CS | I21: 1430-0000 | N21: {=((SUM(IFERROR((TEXT(IF(ISNUMBER(SEARCH("-", F21:L21)), MID(F21:L21, SEARCH("-", F21:L21) + 1, 4), ""), "00\:00") - TEXT(IF(ISNUMBER(SEARCH("-", F21:L21)), MID(F21:L21, SEARCH("-", F21:L21) - 4, 4), ""), "00\:00") + IF(TEXT(IF(ISNUMBER(SEARCH("-", F21:L21)), MID(F21:L21, SEARCH("-", F21:L21) + 1, 4), ""), "00\:00") < TEXT(IF(ISNUMBER(SEARCH("-", F21:L21)), MID(F21:L21, SEARCH("-", F21:L21) - 4, 4), ""), "00\:00"), 1, 0))*24,""))))/9.5} -> 4 | P21: =N21+O21 -> 4 | R21: =IF($C$4=1,SUM(P21+INDIRECT("'Week "&($B$3+1)&"'!P"&(ROW()))),IF($C$4=2,SUM(P21+INDIRECT("'Week "&($B$3-1)&"'!P"&(ROW()))))) -> 8 | S21: =(IFERROR(VLOOKUP(D21,'Employee Numbers'!$A$3:$C$84,3,FALSE),"NOT FOUND"))*8 -> 8 | U21: =COUNTIF(E21:K21,"0800-1730") -> 0 | V21: =COUNTIF(F21:L21,"1???-00?0") -> 1 | W21: =COUNTIF(F21:L21,"*0800-1730*CS*")+COUNTIF(F21:L21,"*0800-1730*DEMT*") -> 3 | Y21: =COUNTIF(K21:L21,"???0-*") -> 0
A22: Paediatric Emergency Consultant | D22: Dr Toby VanHest | E22: =IFERROR(VLOOKUP(D22,'Employee Numbers'!$A$3:$B$84,2,FALSE),"NOT FOUND") -> 609660 | F22: 0800-1730 CS | G22: 0800-1730 CS | H22: 0800-1730 | I22: 1430-0000 | N22: {=((SUM(IFERROR((TEXT(IF(ISNUMBER(SEARCH("-", F22:L22)), MID(F22:L22, SEARCH("-", F22:L22) + 1, 4), ""), "00\:00") - TEXT(IF(ISNUMBER(SEARCH("-", F22:L22)), MID(F22:L22, SEARCH("-", F22:L22) - 4, 4), ""), "00\:00") + IF(TEXT(IF(ISNUMBER(SEARCH("-", F22:L22)), MID(F22:L22, SEARCH("-", F22:L22) + 1, 4), ""), "00\:00") < TEXT(IF(ISNUMBER(SEARCH("-", F22:L22)), MID(F22:L22, SEARCH("-", F22:L22) - 4, 4), ""), "00\:00"), 1, 0))*24,""))))/9.5} -> 4 | P22: =N22+O22 -> 4 | R22: =IF($C$4=1,SUM(P22+INDIRECT("'Week "&($B$3+1)&"'!P"&(ROW()))),IF($C$4=2,SUM(P22+INDIRECT("'Week "&($B$3-1)&"'!P"&(ROW()))))) -> 8 | S22: =(IFERROR(VLOOKUP(D22,'Employee Numbers'!$A$3:$C$84,3,FALSE),"NOT FOUND"))*8 -> 8 | U22: =COUNTIF(E22:K22,"0800-1730") -> 1 | V22: =COUNTIF(F22:L22,"1???-00?0") -> 1 | W22: =COUNTIF(F22:L22,"*0800-1730*CS*")+COUNTIF(F22:L22,"*0800-1730*DEMT*") -> 2 | Y22: =COUNTIF(K22:L22,"???0-*") -> 0
A23: Paediatric Emergency Consultant | D23: Dr Bob Seith | E23: =IFERROR(VLOOKUP(D23,'Employee Numbers'!$A$3:$B$84,2,FALSE),"NOT FOUND") -> 610036 | F23: 0800-1730 CS | G23: 0800-1730 | H23: 0800-1730 | J23: 1430-0000 | N23: {=((SUM(IFERROR((TEXT(IF(ISNUMBER(SEARCH("-", F23:L23)), MID(F23:L23, SEARCH("-", F23:L23) + 1, 4), ""), "00\:00") - TEXT(IF(ISNUMBER(SEARCH("-", F23:L23)), MID(F23:L23, SEARCH("-", F23:L23) - 4, 4), ""), "00\:00") + IF(TEXT(IF(ISNUMBER(SEARCH("-", F23:L23)), MID(F23:L23, SEARCH("-", F23:L23) + 1, 4), ""), "00\:00") < TEXT(IF(ISNUMBER(SEARCH("-", F23:L23)), MID(F23:L23, SEARCH("-", F23:L23) - 4, 4), ""), "00\:00"), 1, 0))*24,""))))/9.5} -> 4 | P23: =N23+O23 -> 4 | R23: =IF($C$4=1,SUM(P23+INDIRECT("'Week "&($B$3+1)&"'!P"&(ROW()))),IF($C$4=2,SUM(P23+INDIRECT("'Week "&($B$3-1)&"'!P"&(ROW()))))) -> 7.8947368 | S23: =(IFERROR(VLOOKUP(D23,'Employee Numbers'!$A$3:$C$84,3,FALSE),"NOT FOUND"))*8 -> 8 | U23: =COUNTIF(E23:K23,"0800-1730") -> 2 | V23: =COUNTIF(F23:L23,"1???-00?0") -> 1 | W23: =COUNTIF(F23:L23,"*0800-1730*CS*")+COUNTIF(F23:L23,"*0800-1730*DEMT*") -> 1 | Y23: =COUNTIF(K23:L23,"???0-*") -> 0
A24: Paediatric Emergency Consultant | D24: Dr Simon Craig | E24: =IFERROR(VLOOKUP(D24,'Employee Numbers'!$A$3:$B$84,2,FALSE),"NOT FOUND") -> 533509 | F24: SAB/L | G24: SAB/L | H24: SAB/L | I24: SAB/L | J24: SAB/L | K24: SAB/L | L24: SAB/L | N24: {=((SUM(IFERROR((TEXT(IF(ISNUMBER(SEARCH("-", F24:L24)), MID(F24:L24, SEARCH("-", F24:L24) + 1, 4), ""), "00\:00") - TEXT(IF(ISNUMBER(SEARCH("-", F24:L24)), MID(F24:L24, SEARCH("-", F24:L24) - 4, 4), ""), "00\:00") + IF(TEXT(IF(ISNUMBER(SEARCH("-", F24:L24)), MID(F24:L24, SEARCH("-", F24:L24) + 1, 4), ""), "00\:00") < TEXT(IF(ISNUMBER(SEARCH("-", F24:L24)), MID(F24:L24, SEARCH("-", F24:L24) - 4, 4), ""), "00\:00"), 1, 0))*24,""))))/9.5} -> 0 | P24: =N24+O24 -> 0 | R24: =IF($C$4=1,SUM(P24+INDIRECT("'Week "&($B$3+1)&"'!P"&(ROW()))),IF($C$4=2,SUM(P24+INDIRECT("'Week "&($B$3-1)&"'!P"&(ROW()))))) -> 0 | S24: =(IFERROR(VLOOKUP(D24,'Employee Numbers'!$A$3:$C$84,3,FALSE),"NOT FOUND"))*8 -> 0 | U24: =COUNTIF(E24:K24,"0800-1730") -> 0 | V24: =COUNTIF(F24:L24,"1???-00?0") -> 0 | W24: =COUNTIF(F24:L24,"*0800-1730*CS*")+COUNTIF(F24:L24,"*0800-1730*DEMT*") -> 0 | Y24: =COUNTIF(K24:L24,"???0-*") -> 0
A25: Paediatric Emergency Consultant | D25: Dr Celia Bagshaw | E25: =IFERROR(VLOOKUP(D25,'Employee Numbers'!$A$3:$B$84,2,FALSE),"NOT FOUND") -> 625985 | F25: 1430-0000 | J25: 0800-1730 0CS | K25: 0800-1730 | L25: 0800-1730 | N25: {=((SUM(IFERROR((TEXT(IF(ISNUMBER(SEARCH("-", F25:L25)), MID(F25:L25, SEARCH("-", F25:L25) + 1, 4), ""), "00\:00") - TEXT(IF(ISNUMBER(SEARCH("-", F25:L25)), MID(F25:L25, SEARCH("-", F25:L25) - 4, 4), ""), "00\:00") + IF(TEXT(IF(ISNUMBER(SEARCH("-", F25:L25)), MID(F25:L25, SEARCH("-", F25:L25) + 1, 4), ""), "00\:00") < TEXT(IF(ISNUMBER(SEARCH("-", F25:L25)), MID(F25:L25, SEARCH("-", F25:L25) - 4, 4), ""), "00\:00"), 1, 0))*24,""))))/9.5} -> 4 | P25: =N25+O25 -> 4 | R25: =IF($C$4=1,SUM(P25+INDIRECT("'Week "&($B$3+1)&"'!P"&(ROW()))),IF($C$4=2,SUM(P25+INDIRECT("'Week "&($B$3-1)&"'!P"&(ROW()))))) -> 8 | S25: =(IFERROR(VLOOKUP(D25,'Employee Numbers'!$A$3:$C$84,3,FALSE),"NOT FOUND"))*8 -> 8 | U25: =COUNTIF(E25:K25,"0800-1730") -> 1 | V25: =COUNTIF(F25:L25,"1???-00?0") -> 1 | W25: =COUNTIF(F25:L25,"*0800-1730*CS*")+COUNTIF(F25:L25,"*0800-1730*DEMT*") -> 1 | Y25: =COUNTIF(K25:L25,"???0-*") -> 2
A26: Paediatric Emergency Consultant | D26: Dr Adnan Bilgrami | E26: =IFERROR(VLOOKUP(D26,'Employee Numbers'!$A$3:$B$84,2,FALSE),"NOT FOUND") -> 632301 | F26: 1430-0000 | G26: 0800-1730 CS | H26: 1430-0000 | J26: 0800-1730 | N26: {=((SUM(IFERROR((TEXT(IF(ISNUMBER(SEARCH("-", F26:L26)), MID(F26:L26, SEARCH("-", F26:L26) + 1, 4), ""), "00\:00") - TEXT(IF(ISNUMBER(SEARCH("-", F26:L26)), MID(F26:L26, SEARCH("-", F26:L26) - 4, 4), ""), "00\:00") + IF(TEXT(IF(ISNUMBER(SEARCH("-", F26:L26)), MID(F26:L26, SEARCH("-", F26:L26) + 1, 4), ""), "00\:00") < TEXT(IF(ISNUMBER(SEARCH("-", F26:L26)), MID(F26:L26, SEARCH("-", F26:L26) - 4, 4), ""), "00\:00"), 1, 0))*24,""))))/9.5} -> 4 | P26: =N26+O26 -> 4 | R26: =IF($C$4=1,SUM(P26+INDIRECT("'Week "&($B$3+1)&"'!P"&(ROW()))),IF($C$4=2,SUM(P26+INDIRECT("'Week "&($B$3-1)&"'!P"&(ROW()))))) -> 8 | S26: =(IFERROR(VLOOKUP(D26,'Employee Numbers'!$A$3:$C$84,3,FALSE),"NOT FOUND"))*8 -> 8 | U26: =COUNTIF(E26:K26,"0800-1730") -> 1 | V26: =COUNTIF(F26:L26,"1???-00?0") -> 2 | W26: =COUNTIF(F26:L26,"*0800-1730*CS*")+COUNTIF(F26:L26,"*0800-1730*DEMT*") -> 1 | Y26: =COUNTIF(K26:L26,"???0-*") -> 0
A27: Paediatric Emergency Consultant | D27: Dr Preeti Ramaswamy | E27: =IFERROR(VLOOKUP(D27,'Employee Numbers'!$A$3:$B$84,2,FALSE),"NOT FOUND") -> 613891 | F27: 1430-0000 | H27: 0800-1730 CS | I27: 0800-1730 | N27: {=((SUM(IFERROR((TEXT(IF(ISNUMBER(SEARCH("-", F27:L27)), MID(F27:L27, SEARCH("-", F27:L27) + 1, 4), ""), "00\:00") - TEXT(IF(ISNUMBER(SEARCH("-", F27:L27)), MID(F27:L27, SEARCH("-", F27:L27) - 4, 4), ""), "00\:00") + IF(TEXT(IF(ISNUMBER(SEARCH("-", F27:L27)), MID(F27:L27, SEARCH("-", F27:L27) + 1, 4), ""), "00\:00") < TEXT(IF(ISNUMBER(SEARCH("-", F27:L27)), MID(F27:L27, SEARCH("-", F27:L27) - 4, 4), ""), "00\:00"), 1, 0))*24,""))))/9.5} -> 3 | P27: =N27+O27 -> 3 | R27: =IF($C$4=1,SUM(P27+INDIRECT("'Week "&($B$3+1)&"'!P"&(ROW()))),IF($C$4=2,SUM(P27+INDIRECT("'Week "&($B$3-1)&"'!P"&(ROW()))))) -> 6 | S27: =(IFERROR(VLOOKUP(D27,'Employee Numbers'!$A$3:$C$84,3,FALSE),"NOT FOUND"))*8 -> 6 | U27: =COUNTIF(E27:K27,"0800-1730") -> 1 | V27: =COUNTIF(F27:L27,"1???-00?0") -> 1 | W27: =COUNTIF(F27:L27,"*0800-1730*CS*")+COUNTIF(F27:L27,"*0800-1730*DEMT*") -> 1 | Y27: =COUNTIF(K27:L27,"???0-*") -> 0
A28: Paediatric Emergency Consultant | D28: Dr Erin Mills | E28: =IFERROR(VLOOKUP(D28,'Employee Numbers'!$A$3:$B$84,2,FALSE),"NOT FOUND") -> 623657 | I28: 0800-1730 | N28: {=((SUM(IFERROR((TEXT(IF(ISNUMBER(SEARCH("-", F28:L28)), MID(F28:L28, SEARCH("-", F28:L28) + 1, 4), ""), "00\:00") - TEXT(IF(ISNUMBER(SEARCH("-", F28:L28)), MID(F28:L28, SEARCH("-", F28:L28) - 4, 4), ""), "00\:00") + IF(TEXT(IF(ISNUMBER(SEARCH("-", F28:L28)), MID(F28:L28, SEARCH("-", F28:L28) + 1, 4), ""), "00\:00") < TEXT(IF(ISNUMBER(SEARCH("-", F28:L28)), MID(F28:L28, SEARCH("-", F28:L28) - 4, 4), ""), "00\:00"), 1, 0))*24,""))))/9.5} -> 1 | P28: =N28+O28 -> 1 | R28: =IF($C$4=1,SUM(P28+INDIRECT("'Week "&($B$3+1)&"'!P"&(ROW()))),IF($C$4=2,SUM(P28+INDIRECT("'Week "&($B$3-1)&"'!P"&(ROW()))))) -> 2 | S28: =(IFERROR(VLOOKUP(D28,'Employee Numbers'!$A$3:$C$84,3,FALSE),"NOT FOUND"))*8 -> 2 | U28: =COUNTIF(E28:K28,"0800-1730") -> 1 | V28: =COUNTIF(F28:L28,"1???-00?0") -> 0 | W28: =COUNTIF(F28:L28,"*0800-1730*CS*")+COUNTIF(F28:L28,"*0800-1730*DEMT*") -> 0 | Y28: =COUNTIF(K28:L28,"???0-*") -> 0
A29: Paediatric Emergency Consultant | D29: Dr Stella Robinson | E29: =IFERROR(VLOOKUP(D29,'Employee Numbers'!$A$3:$B$84,2,FALSE),"NOT FOUND") -> 623708 | G29: 1430-0000 | H29: 0800-1730 CS | J29: 0800-1730 | N29: {=((SUM(IFERROR((TEXT(IF(ISNUMBER(SEARCH("-", F29:L29)), MID(F29:L29, SEARCH("-", F29:L29) + 1, 4), ""), "00\:00") - TEXT(IF(ISNUMBER(SEARCH("-", F29:L29)), MID(F29:L29, SEARCH("-", F29:L29) - 4, 4), ""), "00\:00") + IF(TEXT(IF(ISNUMBER(SEARCH("-", F29:L29)), MID(F29:L29, SEARCH("-", F29:L29) + 1, 4), ""), "00\:00") < TEXT(IF(ISNUMBER(SEARCH("-", F29:L29)), MID(F29:L29, SEARCH("-", F29:L29) - 4, 4), ""), "00\:00"), 1, 0))*24,""))))/9.5} -> 3 | P29: =N29+O29 -> 3 | R29: =IF($C$4=1,SUM(P29+INDIRECT("'Week "&($B$3+1)&"'!P"&(ROW()))),IF($C$4=2,SUM(P29+INDIRECT("'Week "&($B$3-1)&"'!P"&(ROW()))))) -> 6 | S29: =(IFERROR(VLOOKUP(D29,'Employee Numbers'!$A$3:$C$84,3,FALSE),"NOT FOUND"))*8 -> 6 | U29: =COUNTIF(E29:K29,"0800-1730") -> 1 | V29: =COUNTIF(F29:L29,"1???-00?0") -> 1 | W29: =COUNTIF(F29:L29,"*0800-1730*CS*")+COUNTIF(F29:L29,"*0800-1730*DEMT*") -> 1 | Y29: =COUNTIF(K29:L29,"???0-*") -> 0
A30: Paediatric Emergency Consultant | D30: Dr Bev Thompson | E30: =IFERROR(VLOOKUP(D30,'Employee Numbers'!$A$3:$B$84,2,FALSE),"NOT FOUND") -> 627680 | G30: 0800-1730 | H30: 0800-1730 CS | I30: 1430-0000 | N30: {=((SUM(IFERROR((TEXT(IF(ISNUMBER(SEARCH("-", F30:L30)), MID(F30:L30, SEARCH("-", F30:L30) + 1, 4), ""), "00\:00") - TEXT(IF(ISNUMBER(SEARCH("-", F30:L30)), MID(F30:L30, SEARCH("-", F30:L30) - 4, 4), ""), "00\:00") + IF(TEXT(IF(ISNUMBER(SEARCH("-", F30:L30)), MID(F30:L30, SEARCH("-", F30:L30) + 1, 4), ""), "00\:00") < TEXT(IF(ISNUMBER(SEARCH("-", F30:L30)), MID(F30:L30, SEARCH("-", F30:L30) - 4, 4), ""), "00\:00"), 1, 0))*24,""))))/9.5} -> 3 | P30: =N30+O30 -> 3 | R30: =IF($C$4=1,SUM(P30+INDIRECT("'Week "&($B$3+1)&"'!P"&(ROW()))),IF($C$4=2,SUM(P30+INDIRECT("'Week "&($B$3-1)&"'!P"&(ROW()))))) -> 6 | S30: =(IFERROR(VLOOKUP(D30,'Employee Numbers'!$A$3:$C$84,3,FALSE),"NOT FOUND"))*8 -> 6 | U30: =COUNTIF(E30:K30,"0800-1730") -> 1 | V30: =COUNTIF(F30:L30,"1???-00?0") -> 1 | W30: =COUNTIF(F30:L30,"*0800-1730*CS*")+COUNTIF(F30:L30,"*0800-1730*DEMT*") -> 1 | Y30: =COUNTIF(K30:L30,"???0-*") -> 0
A31: Paediatric Emergency Consultant | D31: Dr John Unwin | E31: =IFERROR(VLOOKUP(D31,'Employee Numbers'!$A$3:$B$84,2,FALSE),"NOT FOUND") -> 633210 | G31: 0800-1730 CS | I31: 0800-1730 CS | K31: 0800-1730 | L31: 1500-0030 | N31: {=((SUM(IFERROR((TEXT(IF(ISNUMBER(SEARCH("-", F31:L31)), MID(F31:L31, SEARCH("-", F31:L31) + 1, 4), ""), "00\:00") - TEXT(IF(ISNUMBER(SEARCH("-", F31:L31)), MID(F31:L31, SEARCH("-", F31:L31) - 4, 4), ""), "00\:00") + IF(TEXT(IF(ISNUMBER(SEARCH("-", F31:L31)), MID(F31:L31, SEARCH("-", F31:L31) + 1, 4), ""), "00\:00") < TEXT(IF(ISNUMBER(SEARCH("-", F31:L31)), MID(F31:L31, SEARCH("-", F31:L31) - 4, 4), ""), "00\:00"), 1, 0))*24,""))))/9.5} -> 4 | P31: =N31+O31 -> 4 | R31: =IF($C$4=1,SUM(P31+INDIRECT("'Week "&($B$3+1)&"'!P"&(ROW()))),IF($C$4=2,SUM(P31+INDIRECT("'Week "&($B$3-1)&"'!P"&(ROW()))))) -> 6 | S31: =(IFERROR(VLOOKUP(D31,'Employee Numbers'!$A$3:$C$84,3,FALSE),"NOT FOUND"))*8 -> 6 | U31: =COUNTIF(E31:K31,"0800-1730") -> 1 | V31: =COUNTIF(F31:L31,"1???-00?0") -> 1 | W31: =COUNTIF(F31:L31,"*0800-1730*CS*")+COUNTIF(F31:L31,"*0800-1730*DEMT*") -> 2 | Y31: =COUNTIF(K31:L31,"???0-*") -> 2
A32: Paediatric Emergency Consultant | D32: Dr Siri Samudrala | E32: =IFERROR(VLOOKUP(D32,'Employee Numbers'!$A$3:$B$84,2,FALSE),"NOT FOUND") -> 618952 | F32: 0800-1730 | G32: 1430-0000 | J32: 1430-0000 | N32: {=((SUM(IFERROR((TEXT(IF(ISNUMBER(SEARCH("-", F32:L32)), MID(F32:L32, SEARCH("-", F32:L32) + 1, 4), ""), "00\:00") - TEXT(IF(ISNUMBER(SEARCH("-", F32:L32)), MID(F32:L32, SEARCH("-", F32:L32) - 4, 4), ""), "00\:00") + IF(TEXT(IF(ISNUMBER(SEARCH("-", F32:L32)), MID(F32:L32, SEARCH("-", F32:L32) + 1, 4), ""), "00\:00") < TEXT(IF(ISNUMBER(SEARCH("-", F32:L32)), MID(F32:L32, SEARCH("-", F32:L32) - 4, 4), ""), "00\:00"), 1, 0))*24,""))))/9.5} -> 3 | P32: =N32+O32 -> 3 | R32: =IF($C$4=1,SUM(P32+INDIRECT("'Week "&($B$3+1)&"'!P"&(ROW()))),IF($C$4=2,SUM(P32+INDIRECT("'Week "&($B$3-1)&"'!P"&(ROW()))))) -> 3 | S32: =(IFERROR(VLOOKUP(D32,'Employee Numbers'!$A$3:$C$84,3,FALSE),"NOT FOUND"))*8 -> 6 | U32: =COUNTIF(E32:K32,"0800-1730") -> 1 | V32: =COUNTIF(F32:L32,"1???-00?0") -> 2 | W32: =COUNTIF(F32:L32,"*0800-1730*CS*")+COUNTIF(F32:L32,"*0800-1730*DEMT*") -> 0 | Y32: =COUNTIF(K32:L32,"???0-*") -> 0
A33: Paediatric Emergency Consultant | D33: Dr Tessa Smith | E33: =IFERROR(VLOOKUP(D33,'Employee Numbers'!$A$3:$B$84,2,FALSE),"NOT FOUND") -> 649039 | G33: 1430-0000 | I33: 0800-1730 | N33: {=((SUM(IFERROR((TEXT(IF(ISNUMBER(SEARCH("-", F33:L33)), MID(F33:L33, SEARCH("-", F33:L33) + 1, 4), ""), "00\:00") - TEXT(IF(ISNUMBER(SEARCH("-", F33:L33)), MID(F33:L33, SEARCH("-", F33:L33) - 4, 4), ""), "00\:00") + IF(TEXT(IF(ISNUMBER(SEARCH("-", F33:L33)), MID(F33:L33, SEARCH("-", F33:L33) + 1, 4), ""), "00\:00") < TEXT(IF(ISNUMBER(SEARCH("-", F33:L33)), MID(F33:L33, SEARCH("-", F33:L33) - 4, 4), ""), "00\:00"), 1, 0))*24,""))))/9.5} -> 2 | P33: =N33+O33 -> 2 | R33: =IF($C$4=1,SUM(P33+INDIRECT("'Week "&($B$3+1)&"'!P"&(ROW()))),IF($C$4=2,SUM(P33+INDIRECT("'Week "&($B$3-1)&"'!P"&(ROW()))))) -> 5 | S33: =(IFERROR(VLOOKUP(D33,'Employee Numbers'!$A$3:$C$84,3,FALSE),"NOT FOUND"))*8 -> 5 | U33: =COUNTIF(E33:K33,"0800-1730") -> 1 | V33: =COUNTIF(F33:L33,"1???-00?0") -> 1 | W33: =COUNTIF(F33:L33,"*0800-1730*CS*")+COUNTIF(F33:L33,"*0800-1730*DEMT*") -> 0 | Y33: =COUNTIF(K33:L33,"???0-*") -> 0
A34: Paediatric Emergency Consultant | D34: Dr Brad Dent | E34: =IFERROR(VLOOKUP(D34,'Employee Numbers'!$A$3:$B$84,2,FALSE),"NOT FOUND") -> 649671 | F34: 0800-1730 | G34: 0800-1730 | H34: 1430-0000 | N34: {=((SUM(IFERROR((TEXT(IF(ISNUMBER(SEARCH("-", F34:L34)), MID(F34:L34, SEARCH("-", F34:L34) + 1, 4), ""), "00\:00") - TEXT(IF(ISNUMBER(SEARCH("-", F34:L34)), MID(F34:L34, SEARCH("-", F34:L34) - 4, 4), ""), "00\:00") + IF(TEXT(IF(ISNUMBER(SEARCH("-", F34:L34)), MID(F34:L34, SEARCH("-", F34:L34) + 1, 4), ""), "00\:00") < TEXT(IF(ISNUMBER(SEARCH("-", F34:L34)), MID(F34:L34, SEARCH("-", F34:L34) - 4, 4), ""), "00\:00"), 1, 0))*24,""))))/9.5} -> 3 | P34: =N34+O34 -> 3 | R34: =IF($C$4=1,SUM(P34+INDIRECT("'Week "&($B$3+1)&"'!P"&(ROW()))),IF($C$4=2,SUM(P34+INDIRECT("'Week "&($B$3-1)&"'!P"&(ROW()))))) -> 6 | S34: =(IFERROR(VLOOKUP(D34,'Employee Numbers'!$A$3:$C$84,3,FALSE),"NOT FOUND"))*8 -> 6 | U34: =COUNTIF(E34:K34,"0800-1730") -> 2 | V34: =COUNTIF(F34:L34,"1???-00?0") -> 1 | W34: =COUNTIF(F34:L34,"*0800-1730*CS*")+COUNTIF(F34:L34,"*0800-1730*DEMT*") -> 0 | Y34: =COUNTIF(K34:L34,"???0-*") -> 0
A35: Paediatric Emergency Consultant | D35: Dr Marjolein Slaa | E35: =IFERROR(VLOOKUP(D35,'Employee Numbers'!$A$3:$B$84,2,FALSE),"NOT FOUND") -> 646047 | I35: 0800-1730 CS | K35: 1500-0030 | N35: {=((SUM(IFERROR((TEXT(IF(ISNUMBER(SEARCH("-", F35:L35)), MID(F35:L35, SEARCH("-", F35:L35) + 1, 4), ""), "00\:00") - TEXT(IF(ISNUMBER(SEARCH("-", F35:L35)), MID(F35:L35, SEARCH("-", F35:L35) - 4, 4), ""), "00\:00") + IF(TEXT(IF(ISNUMBER(SEARCH("-", F35:L35)), MID(F35:L35, SEARCH("-", F35:L35) + 1, 4), ""), "00\:00") < TEXT(IF(ISNUMBER(SEARCH("-", F35:L35)), MID(F35:L35, SEARCH("-", F35:L35) - 4, 4), ""), "00\:00"), 1, 0))*24,""))))/9.5} -> 2 | P35: =N35+O35 -> 2 | R35: =IF($C$4=1,SUM(P35+INDIRECT("'Week "&($B$3+1)&"'!P"&(ROW()))),IF($C$4=2,SUM(P35+INDIRECT("'Week "&($B$3-1)&"'!P"&(ROW()))))) -> 4 | S35: =(IFERROR(VLOOKUP(D35,'Employee Numbers'!$A$3:$C$84,3,FALSE),"NOT FOUND"))*8 -> 5 | U35: =COUNTIF(E35:K35,"0800-1730") -> 0 | V35: =COUNTIF(F35:L35,"1???-00?0") -> 1 | W35: =COUNTIF(F35:L35,"*0800-1730*CS*")+COUNTIF(F35:L35,"*0800-1730*DEMT*") -> 1 | Y35: =COUNTIF(K35:L35,"???0-*") -> 1
A36: Paediatric Emergency Consultant | D36: Dr Natalie Hood | E36: =IFERROR(VLOOKUP(D36,'Employee Numbers'!$A$3:$B$84,2,FALSE),"NOT FOUND") -> 164003 | G36: 0800-1730 CSOS | I36: 0800-1730 CS | N36: {=((SUM(IFERROR((TEXT(IF(ISNUMBER(SEARCH("-", F36:L36)), MID(F36:L36, SEARCH("-", F36:L36) + 1, 4), ""), "00\:00") - TEXT(IF(ISNUMBER(SEARCH("-", F36:L36)), MID(F36:L36, SEARCH("-", F36:L36) - 4, 4), ""), "00\:00") + IF(TEXT(IF(ISNUMBER(SEARCH("-", F36:L36)), MID(F36:L36, SEARCH("-", F36:L36) + 1, 4), ""), "00\:00") < TEXT(IF(ISNUMBER(SEARCH("-", F36:L36)), MID(F36:L36, SEARCH("-", F36:L36) - 4, 4), ""), "00\:00"), 1, 0))*24,""))))/9.5} -> 2 | P36: =N36+O36 -> 2 | R36: =IF($C$4=1,SUM(P36+INDIRECT("'Week "&($B$3+1)&"'!P"&(ROW()))),IF($C$4=2,SUM(P36+INDIRECT("'Week "&($B$3-1)&"'!P"&(ROW()))))) -> 4 | S36: =(IFERROR(VLOOKUP(D36,'Employee Numbers'!$A$3:$C$84,3,FALSE),"NOT FOUND"))*8 -> 4 | U36: =COUNTIF(E36:K36,"0800-1730") -> 0 | V36: =COUNTIF(F36:L36,"1???-00?0") -> 0 | W36: =COUNTIF(F36:L36,"*0800-1730*CS*")+COUNTIF(F36:L36,"*0800-1730*DEMT*") -> 2 | Y36: =COUNTIF(K36:L36,"???0-*") -> 0
A37: Paediatric Emergency Consultant | D37: Dr Michael Coman | E37: =IFERROR(VLOOKUP(D37,'Employee Numbers'!$A$3:$B$84,2,FALSE),"NOT FOUND") -> 609408 | N37: {=((SUM(IFERROR((TEXT(IF(ISNUMBER(SEARCH("-", F37:L37)), MID(F37:L37, SEARCH("-", F37:L37) + 1, 4), ""), "00\:00") - TEXT(IF(ISNUMBER(SEARCH("-", F37:L37)), MID(F37:L37, SEARCH("-", F37:L37) - 4, 4), ""), "00\:00") + IF(TEXT(IF(ISNUMBER(SEARCH("-", F37:L37)), MID(F37:L37, SEARCH("-", F37:L37) + 1, 4), ""), "00\:00") < TEXT(IF(ISNUMBER(SEARCH("-", F37:L37)), MID(F37:L37, SEARCH("-", F37:L37) - 4, 4), ""), "00\:00"), 1, 0))*24,""))))/9.5} -> 0 | P37: =N37+O37 -> 0 | R37: =IF($C$4=1,SUM(P37+INDIRECT("'Week "&($B$3+1)&"'!P"&(ROW()))),IF($C$4=2,SUM(P37+INDIRECT("'Week "&($B$3-1)&"'!P"&(ROW()))))) -> 4 | S37: =(IFERROR(VLOOKUP(D37,'Employee Numbers'!$A$3:$C$84,3,FALSE),"NOT FOUND"))*8 -> 4 | U37: =COUNTIF(E37:K37,"0800-1730") -> 0 | V37: =COUNTIF(F37:L37,"1???-00?0") -> 0 | W37: =COUNTIF(F37:L37,"*0800-1730*CS*")+COUNTIF(F37:L37,"*0800-1730*DEMT*") -> 0 | Y37: =COUNTIF(K37:L37,"???0-*") -> 0
A38: Paediatric Emergency Consultant | D38: Dr Andrew Hardy | E38: =IFERROR(VLOOKUP(D38,'Employee Numbers'!$A$3:$B$84,2,FALSE),"NOT FOUND") -> 627619 | G38: 0800-1730 OCS | I38: 0800-1730 CS | N38: {=((SUM(IFERROR((TEXT(IF(ISNUMBER(SEARCH("-", F38:L38)), MID(F38:L38, SEARCH("-", F38:L38) + 1, 4), ""), "00\:00") - TEXT(IF(ISNUMBER(SEARCH("-", F38:L38)), MID(F38:L38, SEARCH("-", F38:L38) - 4, 4), ""), "00\:00") + IF(TEXT(IF(ISNUMBER(SEARCH("-", F38:L38)), MID(F38:L38, SEARCH("-", F38:L38) + 1, 4), ""), "00\:00") < TEXT(IF(ISNUMBER(SEARCH("-", F38:L38)), MID(F38:L38, SEARCH("-", F38:L38) - 4, 4), ""), "00\:00"), 1, 0))*24,""))))/9.5} -> 2 | P38: =N38+O38 -> 2 | R38: =IF($C$4=1,SUM(P38+INDIRECT("'Week "&($B$3+1)&"'!P"&(ROW()))),IF($C$4=2,SUM(P38+INDIRECT("'Week "&($B$3-1)&"'!P"&(ROW()))))) -> 4 | S38: =(IFERROR(VLOOKUP(D38,'Employee Numbers'!$A$3:$C$84,3,FALSE),"NOT FOUND"))*8 -> 4 | U38: =COUNTIF(E38:K38,"0800-1730") -> 0 | V38: =COUNTIF(F38:L38,"1???-00?0") -> 0 | W38: =COUNTIF(F38:L38,"*0800-1730*CS*")+COUNTIF(F38:L38,"*0800-1730*DEMT*") -> 2 | Y38: =COUNTIF(K38:L38,"???0-*") -> 0
A39: Paediatric Emergency Consultant | D39: Dr Gargi Kanabar | E39: =IFERROR(VLOOKUP(D39,'Employee Numbers'!$A$3:$B$84,2,FALSE),"NOT FOUND") -> 632646 | N39: {=((SUM(IFERROR((TEXT(IF(ISNUMBER(SEARCH("-", F39:L39)), MID(F39:L39, SEARCH("-", F39:L39) + 1, 4), ""), "00\:00") - TEXT(IF(ISNUMBER(SEARCH("-", F39:L39)), MID(F39:L39, SEARCH("-", F39:L39) - 4, 4), ""), "00\:00") + IF(TEXT(IF(ISNUMBER(SEARCH("-", F39:L39)), MID(F39:L39, SEARCH("-", F39:L39) + 1, 4), ""), "00\:00") < TEXT(IF(ISNUMBER(SEARCH("-", F39:L39)), MID(F39:L39, SEARCH("-", F39:L39) - 4, 4), ""), "00\:00"), 1, 0))*24,""))))/9.5} -> 0 | P39: =N39+O39 -> 0 | R39: =IF($C$4=1,SUM(P39+INDIRECT("'Week "&($B$3+1)&"'!P"&(ROW()))),IF($C$4=2,SUM(P39+INDIRECT("'Week "&($B$3-1)&"'!P"&(ROW()))))) -> 4 | S39: =(IFERROR(VLOOKUP(D39,'Employee Numbers'!$A$3:$C$84,3,FALSE),"NOT FOUND"))*8 -> 4 | U39: =COUNTIF(E39:K39,"0800-1730") -> 0 | V39: =COUNTIF(F39:L39,"1???-00?0") -> 0 | W39: =COUNTIF(F39:L39,"*0800-1730*CS*")+COUNTIF(F39:L39,"*0800-1730*DEMT*") -> 0 | Y39: =COUNTIF(K39:L39,"???0-*") -> 0
A40: Paediatric Emergency Consultant | D40: Dr Mandy Parr | E40: =IFERROR(VLOOKUP(D40,'Employee Numbers'!$A$3:$B$84,2,FALSE),"NOT FOUND") -> 652844 | G40: 0800-1730 CS | H40: 1430-0000 | J40: 0800-1730 | K40: 1500-0030 | N40: {=((SUM(IFERROR((TEXT(IF(ISNUMBER(SEARCH("-", F40:L40)), MID(F40:L40, SEARCH("-", F40:L40) + 1, 4), ""), "00\:00") - TEXT(IF(ISNUMBER(SEARCH("-", F40:L40)), MID(F40:L40, SEARCH("-", F40:L40) - 4, 4), ""), "00\:00") + IF(TEXT(IF(ISNUMBER(SEARCH("-", F40:L40)), MID(F40:L40, SEARCH("-", F40:L40) + 1, 4), ""), "00\:00") < TEXT(IF(ISNUMBER(SEARCH("-", F40:L40)), MID(F40:L40, SEARCH("-", F40:L40) - 4, 4), ""), "00\:00"), 1, 0))*24,""))))/9.5} -> 4 | P40: =N40+O40 -> 4 | R40: =IF($C$4=1,SUM(P40+INDIRECT("'Week "&($B$3+1)&"'!P"&(ROW()))),IF($C$4=2,SUM(P40+INDIRECT("'Week "&($B$3-1)&"'!P"&(ROW()))))) -> 4 | S40: =(IFERROR(VLOOKUP(D40,'Employee Numbers'!$A$3:$C$84,3,FALSE),"NOT FOUND"))*8 -> 4 | U40: =COUNTIF(E40:K40,"0800-1730") -> 1 | V40: =COUNTIF(F40:L40,"1???-00?0") -> 2 | W40: =COUNTIF(F40:L40,"*0800-1730*CS*")+COUNTIF(F40:L40,"*0800-1730*DEMT*") -> 1 | Y40: =COUNTIF(K40:L40,"???0-*") -> 1
